Workbook

Sheet 2025년
B2: 2025년도 | D2: 6월 | E2: 7월 | F2: 8월 | G2: 9월 | H2: 10월 | I2: 11월 | J2: 12월 | K2: 합계 | L2: 월평균
B3: 출고건수 | C3: OPS | D3: ='6월'!T34 -> 256567 | E3: ='7월'!U35 -> 106633 | F3: ='8월'!Q35 -> 113192 | G3: ='9월'!S34 -> 415484 | H3: ='10월'!Q36 -> 95914 | I3: ='11월'!BJ36 -> 355106 | J3: ='12월'!BJ37 -> 277268 | K3: =SUM(D3:J3) -> 1620164 | L3: =K3/7 -> 231452
C4: 풀필 | D4: ='6월'!X34 -> 93535 | E4: ='7월'!Y35 -> 59743 | F4: ='8월'!U35 -> 54057 | G4: ='9월'!W34 -> 91925 | H4: ='10월'!U36 -> 50947 | I4: ='11월'!BO36 -> 122307 | J4: ='12월'!BN37+'12월'!BR37 -> 92081 | K4: =SUM(D4:J4) -> 564595 | L4: =K4/7 -> 80656.429

Sheet 6월
A1: 일자 | B1: 요일 | C1: 운영 근무자 | N1: 운영 근무자 잔업 | T1: OPS 출하건수 | X1: WMS 작업건수 | AB1: B2B | AC1: WMG | AG1: 비고
C2: 정직원 | J2: 협력사원 | M2: 단기충원사유
C3: 센터장 및 지원 | D3: 입고 | E3: QFC | F3: OPS | G3: 예외 | H3: 드라이버 | I3: 합계 | J3: 장기협력사원 | K3: 단기협력사원 | L3: 합계 | N3: OPS, QFC | O3: 에러,입고,픽업 | P3: 장기협력사원 | Q3: 단기협력사원 | R3: 잔업시간(분) | S3: 잔업사유 | T3: KR-All | U3: KRKR | V3: KR-Oversea | W3: KRJP | X3: KR-All | Y3: KRKR | Z3: KR-Oversea | AA3: KRJP | AB3: 출고 건수 | AC3: 입고건수 | AD3: 출고건수 | AE3: 반송 | AF3: 미출고
A4: 45809 | B4: 일 | C4: 3 | D4: 2 | E4: 7 | F4: 4 | G4: 2 | H4: 2 | I4: =C4+D4+E4+F4+G4+H4 -> 20 | J4: 7 | K4: 1 | L4: =J4+K4 -> 8 | M4: OPS출고 | P4: 0 | Q4: 0 | R4: 0 | T4: =U4+V4+W4 -> 4484 | U4: 0 | V4: 3 | W4: 4481 | X4: =Y4+Z4+AA4 -> 4182 | Y4: 0 | Z4: 0 | AA4: 4182 | AB4: 0 | AC4: 0 | AD4: 0 | AE4: 0 | AF4: =AC4-AD4-AE4 -> 0
A5: 45810 | B5: 월 | C5: 3 | D5: 2 | E5: 7 | F5: 4 | G5: 2 | H5: 2 | I5: =C5+D5+E5+F5+G5+H5 -> 20 | J5: 7 | K5: 40.5 | L5: =J5+K5 -> 47.5 | M5: 메가와리 출고 | N5: 20 | P5: 7 | Q5: 15 | R5: 180 | S5: 메가와리출고 | T5: =U5+V5+W5 -> 18464 | U5: 0 | V5: 10 | W5: 18454 | X5: =Y5+Z5+AA5 -> 8508 | Y5: 2346 | Z5: 48 | AA5: 6114 | AB5: 56 | AC5: 0 | AD5: 0 | AE5: 0 | AF5: =AF4+AC5-AD5-AE5 -> 0
A6: 45811 | B6: 화 | C6: 3 | D6: 2 | E6: 7 | F6: 4 | G6: 2 | H6: 2 | I6: =C6+D6+E6+F6+G6+H6 -> 20 | J6: 7 | K6: 21 | L6: =J6+K6 -> 28 | M6: 메가와리 출고 | P6: 0 | Q6: 0 | R6: 0 | T6: =U6+V6+W6 -> 8346 | U6: 0 | V6: 0 | W6: 8346 | X6: =Y6+Z6+AA6 -> 4039 | Y6: 0 | Z6: 0 | AA6: 4039 | AB6: 0 | AC6: 0 | AD6: 0 | AE6: 0 | AF6: =AF5+AC6-AD6-AE6 -> 0
A7: 45812 | B7: 수 | C7: 3 | D7: 2 | E7: 7 | F7: 5 | G7: 2 | H7: 2 | I7: =C7+D7+E7+F7+G7+H7 -> 21 | J7: 7 | K7: 43 | L7: =J7+K7 -> 50 | M7: 메가와리 출고 | N7: 21 | P7: 7 | Q7: 38 | R7: 180 | S7: 메가와리출고 | T7: =U7+V7+W7 -> 28227 | U7: 0 | V7: 22 | W7: 28205 | X7: =Y7+Z7+AA7 -> 7787 | Y7: 1657 | Z7: 47 | AA7: 6083 | AB7: 2 | AC7: 0 | AD7: 0 | AE7: 0 | AF7: =AF6+AC7-AD7-AE7 -> 0
A8: 45813 | B8: 목 | C8: 3 | D8: 2 | E8: 7 | F8: 5 | G8: 2 | H8: 2 | I8: =C8+D8+E8+F8+G8+H8 -> 21 | J8: 7 | K8: 44.5 | L8: =J8+K8 -> 51.5 | M8: 메가와리 출고 | N8: 21 | P8: 7 | Q8: 38 | R8: 180 | S8: 메가와리출고 | T8: =U8+V8+W8 -> 30920 | U8: 0 | V8: 66 | W8: 30854 | X8: =Y8+Z8+AA8 -> 6902 | Y8: 976 | Z8: 11 | AA8: 5915 | AB8: 13 | AC8: 0 | AD8: 0 | AE8: 0 | AF8: =AF7+AC8-AD8-AE8 -> 0
A9: 45814 | B9: 금 | C9: 3 | D9: 2 | E9: 7 | F9: 4 | G9: 2 | H9: 1 | I9: =C9+D9+E9+F9+G9+H9 -> 19 | J9: 7 | K9: 33 | L9: =J9+K9 -> 40 | M9: 메가와리 출고 | N9: 0 | P9: 0 | Q9: 0 | R9: 0 | T9: =U9+V9+W9 -> 8461 | U9: 0 | V9: 46 | W9: 8415 | X9: =Y9+Z9+AA9 -> 3752 | Y9: 0 | Z9: 0 | AA9: 3752 | AB9: 0 | AC9: 0 | AD9: 0 | AE9: 0 | AF9: =AF8+AC9-AD9-AE9 -> 0
A10: 45815 | B10: 토 | C10: 3 | D10: 2 | E10: 7 | F10: 4 | G10: 2 | H10: 2 | I10: =C10+D10+E10+F10+G10+H10 -> 20 | J10: 6.5 | K10: 1 | L10: =J10+K10 -> 7.5 | M10: OPS출고 | N10: 0 | P10: 0 | Q10: 0 | R10: 0 | T10: =U10+V10+W10 -> 6145 | U10: 0 | V10: 41 | W10: 6104 | X10: =Y10+Z10+AA10 -> 1664 | Y10: 0 | Z10: 1 | AA10: 1663 | AB10: 0 | AC10: 0 | AD10: 0 | AE10: 0 | AF10: =AF9+AC10-AD10-AE10 -> 0
A11: 45816 | B11: 일 | C11: 3 | D11: 2 | E11: 7 | F11: 4 | G11: 2 | H11: 2 | I11: =C11+D11+E11+F11+G11+H11 -> 20 | J11: 5 | K11: 1 | L11: =J11+K11 -> 6 | M11: OPS출고 | N11: 0 | P11: 0 | Q11: 0 | R11: 0 | T11: =U11+V11+W11 -> 3290 | U11: 0 | V11: 0 | W11: 3290 | X11: =Y11+Z11+AA11 -> 1407 | Y11: 0 | Z11: 0 | AA11: 1407 | AB11: 0 | AC11: 0 | AD11: 0 | AE11: 0 | AF11: =AF10+AC11-AD11-AE11 -> 0
A12: 45817 | B12: 월 | C12: 3 | D12: 2 | E12: 7 | F12: 4 | G12: 2 | H12: 2 | I12: =C12+D12+E12+F12+G12+H12 -> 20 | J12: 7 | K12: 23 | L12: =J12+K12 -> 30 | M12: 메가와리 출고 | N12: 20 | P12: 6 | Q12: 23 | R12: 180 | S12: 메가와리출고 | T12: =U12+V12+W12 -> 15305 | U12: 0 | V12: 161 | W12: 15144 | X12: =Y12+Z12+AA12 -> 8479 | Y12: 2868 | Z12: 199 | AA12: 5412 | AB12: 3 | AC12: 0 | AD12: 0 | AE12: 0 | AF12: =AF11+AC12-AD12-AE12 -> 0
A13: 45818 | B13: 화 | C13: 3 | D13: 2 | E13: 7 | F13: 4 | G13: 2 | H13: 2 | I13: =C13+D13+E13+F13+G13+H13 -> 20 | J13: 7 | K13: 38 | L13: =J13+K13 -> 45 | M13: 메가와리 출고 | N13: 20 | P13: 6 | Q13: 37 | R13: 180 | S13: 메가와리출고 | T13: =U13+V13+W13 -> 31244 | U13: 0 | V13: 50 | W13: 31194 | X13: =Y13+Z13+AA13 -> 7406 | Y13: 905 | Z13: 55 | AA13: 6446 | AB13: 5 | AC13: 0 | AD13: 0 | AE13: 0 | AF13: =AF12+AC13-AD13-AE13 -> 0
A14: 45819 | B14: 수 | C14: 3 | D14: 2 | E14: 7 | F14: 4 | G14: 2 | H14: 2 | I14: =C14+D14+E14+F14+G14+H14 -> 20 | J14: 7 | K14: 36 | L14: =J14+K14 -> 43 | M14: 메가와리 출고 | N14: 0 | P14: 0 | Q14: 0 | R14: 0 | T14: =U14+V14+W14 -> 15262 | U14: 0 | V14: 78 | W14: 15184 | X14: =Y14+Z14+AA14 -> 3662 | Y14: 866 | Z14: 22 | AA14: 2774 | AB14: 0 | AC14: 0 | AD14: 0 | AE14: 0 | AF14: =AF13+AC14-AD14-AE14 -> 0
A15: 45820 | B15: 목 | C15: 3 | D15: 2 | E15: 7 | F15: 4 | G15: 2 | H15: 2 | I15: =C15+D15+E15+F15+G15+H15 -> 20 | J15: 5.5 | K15: 26 | L15: =J15+K15 -> 31.5 | M15: 메가와리 출고 | N15: 20 | P15: 4 | Q15: 24 | R15: 180 | S15: 메가와리출고 | T15: =U15+V15+W15 -> 15450 | U15: 0 | V15: 64 | W15: 15386 | X15: =Y15+Z15+AA15 -> 4842 | Y15: 1732 | Z15: 17 | AA15: 3093 | AB15: 3 | AC15: 0 | AD15: 0 | AE15: 0 | AF15: =AF14+AC15-AD15-AE15 -> 0
A16: 45821 | B16: 금 | C16: 3 | D16: 2 | E16: 7 | F16: 4 | G16: 2 | H16: 2 | I16: =C16+D16+E16+F16+G16+H16 -> 20 | J16: 7 | K16: 24 | L16: =J16+K16 -> 31 | M16: 메가와리 출고 | N16: 20 | P16: 7 | Q16: 20 | R16: 90 | S16: 메가와리출고 | T16: =U16+V16+W16 -> 15035 | U16: 0 | V16: 49 | W16: 14986 | X16: =Y16+Z16+AA16 -> 5969 | Y16: 840 | Z16: 23 | AA16: 5106 | AB16: 58 | AC16: 0 | AD16: 0 | AE16: 0 | AF16: =AF15+AC16-AD16-AE16 -> 0
A17: 45822 | B17: 토 | C17: 3 | D17: 2 | E17: 7 | F17: 4 | G17: 2 | H17: 2 | I17: =C17+D17+E17+F17+G17+H17 -> 20 | J17: 5 | K17: 1 | L17: =J17+K17 -> 6 | M17: OPS출고 | N17: 0 | P17: 0 | Q17: 0 | R17: 0 | T17: =U17+V17+W17 -> 7081 | U17: 0 | V17: 23 | W17: 7058 | X17: =Y17+Z17+AA17 -> 453 | Y17: 1 | Z17: 0 | AA17: 452 | AB17: 0 | AC17: 0 | AD17: 0 | AE17: 0 | AF17: =AF16+AC17-AD17-AE17 -> 0
A18: 45823 | B18: 일 | C18: 2 | D18: 0 | E18: 1 | F18: 1 | G18: 0 | H18: 0 | I18: =C18+D18+E18+F18+G18+H18 -> 4 | J18: 0 | K18: 0 | L18: =J18+K18 -> 0 | N18: 0 | P18: 0 | Q18: 0 | R18: 0 | T18: =U18+V18+W18 -> 0 | U18: 0 | V18: 0 | W18: 0 | X18: =Y18+Z18+AA18 -> 0 | Y18: 0 | Z18: 0 | AA18: 0 | AB18: 0 | AC18: 0 | AD18: 0 | AE18: 0 | AF18: =AF17+AC18-AD18-AE18 -> 0
A19: 45824 | B19: 월 | C19: 3 | D19: 1 | E19: 7 | F19: 4 | G19: 2 | H19: 2 | I19: =C19+D19+E19+F19+G19+H19 -> 19 | J19: 7 | K19: 16 | L19: =J19+K19 -> 23 | N19: 19 | P19: 7 | Q19: 14 | R19: 120 | S19: 메가와리출고 | T19: =U19+V19+W19 -> 10943 | U19: 0 | V19: 87 | W19: 10856 | X19: =Y19+Z19+AA19 -> 3575 | Y19: 3061 | Z19: 144 | AA19: 370 | AB19: 4 | AC19: 0 | AD19: 0 | AE19: 0 | AF19: =AF18+AC19-AD19-AE19 -> 0
A20: 45825 | B20: 화 | C20: 3 | D20: 2 | E20: 7 | F20: 3 | G20: 2 | H20: 2 | I20: =C20+D20+E20+F20+G20+H20 -> 19 | J20: 7 | K20: 15 | L20: =J20+K20 -> 22 | N20: 0 | P20: 0 | Q20: 0 | R20: 0 | T20: =U20+V20+W20 -> 7893 | U20: 0 | V20: 183 | W20: 7710 | X20: =Y20+Z20+AA20 -> 3457 | Y20: 1011 | Z20: 85 | AA20: 2361 | AB20: 1 | AC20: 0 | AD20: 0 | AE20: 0 | AF20: =AF19+AC20-AD20-AE20 -> 0
A21: 45826 | B21: 수 | C21: 3 | D21: 2 | E21: 6.5 | F21: 4 | G21: 2 | H21: 2 | I21: =C21+D21+E21+F21+G21+H21 -> 19.5 | J21: 6 | K21: 6 | L21: =J21+K21 -> 12 | M21: 재고조사/임가공/출고 | N21: 0 | P21: 0 | Q21: 0 | R21: 0 | T21: =U21+V21+W21 -> 3894 | U21: 0 | V21: 55 | W21: 3839 | X21: =Y21+Z21+AA21 -> 1543 | Y21: 861 | Z21: 53 | AA21: 629 | AB21: 23 | AC21: 0 | AD21: 0 | AE21: 0 | AF21: =AF20+AC21-AD21-AE21 -> 0
A22: 45827 | B22: 목 | C22: 3 | D22: 2 | E22: 7 | F22: 4 | G22: 2 | H22: 2 | I22: =C22+D22+E22+F22+G22+H22 -> 20 | J22: 6 | K22: 7 | L22: =J22+K22 -> 13 | M22: 재고조사/임가공/출고 | N22: 0 | P22: 0 | Q22: 0 | R22: 0 | T22: =U22+V22+W22 -> 2780 | U22: 0 | V22: 45 | W22: 2735 | X22: =Y22+Z22+AA22 -> 1224 | Y22: 741 | Z22: 52 | AA22: 431 | AB22: 24 | AC22: 0 | AD22: 0 | AE22: 0 | AF22: =AF21+AC22-AD22-AE22 -> 0
A23: 45828 | B23: 금 | C23: 2 | D23: 2 | E23: 7 | F23: 4 | G23: 2 | H23: 2 | I23: =C23+D23+E23+F23+G23+H23 -> 19 | J23: 5 | K23: 7 | L23: =J23+K23 -> 12 | M23: 재고조사/임가공/출고 | N23: 0 | P23: 0 | Q23: 0 | R23: 0 | T23: =U23+V23+W23 -> 2330 | U23: 0 | V23: 34 | W23: 2296 | X23: =Y23+Z23+AA23 -> 1223 | Y23: 727 | Z23: 15 | AA23: 481 | AB23: 36 | AC23: 0 | AD23: 0 | AE23: 0 | AF23: =AF22+AC23-AD23-AE23 -> 0
A24: 45829 | B24: 토 | C24: 0 | D24: 0 | E24: 3 | F24: 1 | G24: 1 | H24: 0 | I24: =C24+D24+E24+F24+G24+H24 -> 5 | J24: 0 | K24: 0 | L24: =J24+K24 -> 0 | N24: 0 | P24: 0 | Q24: 0 | R24: 0 | T24: =U24+V24+W24 -> 347 | U24: 0 | V24: 2 | W24: 345 | X24: =Y24+Z24+AA24 -> 85 | Y24: 0 | Z24: 0 | AA24: 85 | AB24: 0 | AC24: 0 | AD24: 0 | AE24: 0 | AF24: =AF23+AC24-AD24-AE24 -> 0
A25: 45830 | B25: 일 | C25: 0 | D25: 0 | E25: 2 | F25: 1 | G25: 1 | H25: 1 | I25: =C25+D25+E25+F25+G25+H25 -> 5 | J25: 0 | K25: 0 | L25: =J25+K25 -> 0 | N25: 0 | P25: 0 | Q25: 0 | R25: 0 | T25: =U25+V25+W25 -> 436 | U25: 0 | V25: 7 | W25: 429 | X25: =Y25+Z25+AA25 -> 102 | Y25: 0 | Z25: 0 | AA25: 102 | AB25: 0 | AC25: 0 | AD25: 0 | AE25: 0 | AF25: =AF24+AC25-AD25-AE25 -> 0
A26: 45831 | B26: 월 | C26: 3 | D26: 2 | E26: 7 | F26: 4 | G26: 2 | H26: 1 | I26: =C26+D26+E26+F26+G26+H26 -> 19 | J26: 7 | K26: 8 | L26: =J26+K26 -> 15 | M26: 재고조사/출고 | N26: 0 | P26: 0 | Q26: 0 | R26: 0 | T26: =U26+V26+W26 -> 2429 | U26: 0 | V26: 56 | W26: 2373 | X26: =Y26+Z26+AA26 -> 3460 | Y26: 2269 | Z26: 64 | AA26: 1127 | AB26: 2 | AC26: 0 | AD26: 0 | AE26: 0 | AF26: =AF25+AC26-AD26-AE26 -> 0
A27: 45832 | B27: 화 | C27: 3 | D27: 2 | E27: 7 | F27: 3 | G27: 2 | H27: 2 | I27: =C27+D27+E27+F27+G27+H27 -> 19 | J27: 7 | K27: 4 | L27: =J27+K27 -> 11 | M27: 재고조사/출고 | N27: 0 | P27: 0 | Q27: 0 | R27: 0 | T27: =U27+V27+W27 -> 4319 | U27: 0 | V27: 72 | W27: 4247 | X27: =Y27+Z27+AA27 -> 1474 | Y27: 770 | Z27: 180 | AA27: 524 | AB27: 1 | AC27: 0 | AD27: 0 | AE27: 0 | AF27: =AF26+AC27-AD27-AE27 -> 0
A28: 45833 | B28: 수 | C28: 3 | D28: 2 | E28: 7 | F28: 3 | G28: 2 | H28: 2 | I28: =C28+D28+E28+F28+G28+H28 -> 19 | J28: 6 | K28: 4 | L28: =J28+K28 -> 10 | M28: 재고조사/출고 | N28: 0 | P28: 0 | Q28: 0 | R28: 0 | T28: =U28+V28+W28 -> 3361 | U28: 0 | V28: 73 | W28: 3288 | X28: =Y28+Z28+AA28 -> 1393 | Y28: 789 | Z28: 38 | AA28: 566 | AB28: 3 | AC28: 0 | AD28: 0 | AE28: 0 | AF28: =AF27+AC28-AD28-AE28 -> 0
A29: 45834 | B29: 목 | C29: 2.5 | D29: 2 | E29: 5.5 | F29: 4 | G29: 2 | H29: 1 | I29: =C29+D29+E29+F29+G29+H29 -> 17 | J29: 6.5 | K29: 3 | L29: =J29+K29 -> 9.5 | M29: 재고조사/출고 | N29: 0 | P29: 0 | Q29: 0 | R29: 0 | T29: =U29+V29+W29 -> 3848 | U29: 0 | V29: 59 | W29: 3789 | X29: =Y29+Z29+AA29 -> 2326 | Y29: 900 | Z29: 40 | AA29: 1386 | AB29: 29 | AC29: 0 | AD29: 0 | AE29: 0 | AF29: =AF28+AC29-AD29-AE29 -> 0
A30: 45835 | B30: 금 | C30: 3 | D30: 2 | E30: 4 | F30: 4 | G30: 2 | H30: 2 | I30: =C30+D30+E30+F30+G30+H30 -> 17 | J30: 6 | K30: 4 | L30: =J30+K30 -> 10 | M30: 재고조사/출고 | N30: 0 | P30: 0 | Q30: 0 | R30: 0 | T30: =U30+V30+W30 -> 2390 | U30: 0 | V30: 44 | W30: 2346 | X30: =Y30+Z30+AA30 -> 1294 | Y30: 848 | Z30: 38 | AA30: 408 | AB30: 7 | AC30: 69 | AD30: 0 | AE30: 3 | AF30: =AF29+AC30-AD30-AE30 -> 66
A31: 45836 | B31: 토 | C31: 0 | D31: 0 | E31: 0 | F31: 0 | G31: 0 | H31: 0 | I31: =C31+D31+E31+F31+G31+H31 -> 0 | J31: 0 | K31: 0 | L31: =J31+K31 -> 0 | N31: 0 | P31: 0 | Q31: 0 | R31: 0 | T31: =U31+V31+W31 -> 0 | U31: 0 | V31: 0 | W31: 0 | X31: =Y31+Z31+AA31 -> 0 | Y31: 0 | Z31: 0 | AA31: 0 | AB31: 0 | AC31: 0 | AD31: 0 | AE31: 0 | AF31: =AF30+AC31-AD31-AE31 -> 66
A32: 45837 | B32: 일 | C32: 0 | D32: 0 | E32: 0 | F32: 0 | G32: 0 | H32: 0 | I32: =C32+D32+E32+F32+G32+H32 -> 0 | J32: 0 | K32: 0 | L32: =J32+K32 -> 0 | N32: 0 | P32: 0 | Q32: 0 | R32: 0 | T32: =U32+V32+W32 -> 0 | U32: 0 | V32: 0 | W32: 0 | X32: =Y32+Z32+AA32 -> 0 | Y32: 0 | Z32: 0 | AA32: 0 | AB32: 0 | AC32: 0 | AD32: 0 | AE32: 0 | AF32: =AF31+AC32-AD32-AE32 -> 66
A33: 45838 | B33: 월 | C33: 3 | D33: 2 | E33: 7 | F33: 4 | G33: 2 | H33: 2 | I33: =C33+D33+E33+F33+G33+H33 -> 20 | J33: 7 | K33: 5 | L33: =J33+K33 -> 12 | M33: 재고조사/출고 | N33: 0 | P33: 0 | Q33: 0 | R33: 0 | T33: =U33+V33+W33 -> 3883 | U33: 0 | V33: 48 | W33: 3835 | X33: =Y33+Z33+AA33 -> 3327 | Y33: 2252 | Z33: 95 | AA33: 980 | AB33: 0 | AC33: 19 | AD33: 0 | AE33: 0 | AF33: =AF32+AC33-AD33-AE33 -> 85
A34: 합계 | C34: =SUM(C4:C33) -> 75.5 | D34: =SUM(D4:D33) -> 49 | E34: =SUM(E4:E33) -> 176 | F34: =SUM(F4:F33) -> 102 | G34: =SUM(G4:G33) -> 52 | H34: =SUM(H4:H33) -> 48 | I34: =SUM(I4:I33) -> 502.5 | J34: =SUM(J4:J33) -> 162.5 | ... L34: =SUM(L4:L33) -> 574.5 | T34: =SUM(T4:T33) -> 256567 | U34: =SUM(U4:U33) -> 0 | V34: =SUM(V4:V33) -> 1378 | W34: =SUM(W4:W33) -> 255189 | X34: =SUM(X4:X33) -> 93535 | Y34: =SUM(Y4:Y33) -> 26420 | Z34: =SUM(Z4:Z33) -> 1227 | AA34: =SUM(AA4:AA33) -> 65888 | ... AE34: =SUM(AE4:AE33) -> 3

Sheet 7월
A1: 일자 | B1: 요일 | C1: 운영 근무자 | N1: 운영 근무자 잔업 | T1: 영종ALL | U1: OPS 출하건수 | Y1: WMS 작업건수 | AC1: B2B | AD1: WMG | AH1: 비고
C2: 정직원 | J2: 협력사원 | M2: 단기충원사유
C3: 센터장 및 지원 | D3: 입고 | E3: QFC | F3: OPS | G3: 예외 | H3: 드라이버 | I3: 합계 | J3: 장기협력사원 | K3: 단기협력사원 | L3: 합계 | N3: OPS, QFC | O3: 에러,입고,픽업 | P3: 장기협력사원 | Q3: 단기협력사원 | R3: 잔업시간(분) | S3: 잔업사유 | T3: ALL | U3: KR-All | V3: KRKR | W3: KR-Oversea | X3: KRJP | Y3: KR-All | Z3: KRKR | AA3: KR-Oversea | AB3: KRJP | AC3: 출고 건수 | AD3: 입고건수 | AE3: 출고건수 | AF3: 반송 | AG3: 미출고
A4: 45839 | B4: 화 | C4: 3 | D4: 2 | E4: 7 | F4: 3 | G4: 2 | H4: 2 | I4: =C4+D4+E4+F4+G4+H4 -> 19 | J4: 6 | K4: 3 | L4: =J4+K4 -> 9 | M4: 재고 2 / 출고 1 | T4: =U4+Z4 -> 5462 | U4: =V4+W4+X4 -> 4522 | V4: 0 | W4: 37 | X4: 4485 | Y4: =Z4+AA4+AB4 -> 2129 | Z4: 940 | AA4: 21 | AB4: 1168 | AC4: 11 | AD4: 213 | AE4: 85 | AF4: 0 | AG4: =85+AD4-AE4 -> 213
A5: 45840 | B5: 수 | C5: 3 | D5: 2 | E5: 7 | F5: 4 | G5: 2 | H5: 2 | I5: =C5+D5+E5+F5+G5+H5 -> 20 | J5: 6 | K5: 3 | L5: =J5+K5 -> 9 | M5: 재고 2 / 출고 1 | N5: 19 | P5: 6 | Q5: 3 | R5: 90 | S5: 풀필먼트출고 | T5: =U5+Z5 -> 8059 | U5: =V5+W5+X5 -> 7176 | V5: 0 | W5: 71 | X5: 7105 | Y5: =Z5+AA5+AB5 -> 3149 | Z5: 883 | AA5: 66 | AB5: 2200 | AC5: 3 | AD5: 113 | AE5: 0 | AF5: 0 | AG5: =AG4+AD5-AE5-AF5 -> 326
A6: 45841 | B6: 목 | C6: 3 | D6: 1.5 | E6: 7 | F6: 4 | G6: 2 | H6: 2 | I6: =C6+D6+E6+F6+G6+H6 -> 19.5 | J6: 7 | K6: 3 | L6: =J6+K6 -> 10 | M6: 재고 2 / 출고 1 | N6: 1 | R6: 210 | S6: 정산 | T6: =U6+Z6 -> 5905 | U6: =V6+W6+X6 -> 4966 | V6: 0 | W6: 23 | X6: 4943 | Y6: =Z6+AA6+AB6 -> 2151 | Z6: 939 | AA6: 111 | AB6: 1101 | AC6: 22 | AD6: 51 | AE6: 325 | AF6: 0 | AG6: =AG5+AD6-AE6-AF6 -> 52
A7: 45842 | B7: 금 | C7: 2 | D7: 2 | E7: 6 | F7: 4 | G7: 2 | H7: 2 | I7: =C7+D7+E7+F7+G7+H7 -> 18 | J7: 6.5 | K7: 2 | L7: =J7+K7 -> 8.5 | M7: 출고 2 | T7: =U7+Z7 -> 6545 | U7: =V7+W7+X7 -> 5710 | V7: 0 | W7: 66 | X7: 5644 | Y7: =Z7+AA7+AB7 -> 2201 | Z7: 835 | AA7: 43 | AB7: 1323 | AC7: 1 | AD7: 32 | AE7: 78 | AF7: 0 | AG7: =AG6+AD7-AE7-AF7 -> 6
A8: 45843 | B8: 토 | C8: 0 | D8: 0 | E8: 0 | F8: 0 | G8: 0 | H8: 0 | I8: =C8+D8+E8+F8+G8+H8 -> 0 | J8: =M8+N8+P8 -> 0 | K8: =M8+N8+P8 -> 0 | L8: =J8+K8 -> 0 | T8: =U8+Z8 -> 0 | U8: =V8+W8+X8 -> 0 | V8: 0 | W8: 0 | X8: 0 | Y8: =Z8+AA8+AB8 -> 0 | Z8: 0 | AA8: 0 | AB8: 0 | AC8: 0 | AD8: 0 | AE8: 0 | AF8: 0 | AG8: =AG7+AD8-AE8-AF8 -> 6
A9: 45844 | B9: 일 | C9: 0 | D9: 0 | E9: 0 | F9: 0 | G9: 0 | H9: 0 | I9: =C9+D9+E9+F9+G9+H9 -> 0 | J9: =M9+N9+P9 -> 0 | K9: =M9+N9+P9 -> 0 | L9: =J9+K9 -> 0 | T9: =U9+Z9 -> 0 | U9: =V9+W9+X9 -> 0 | V9: 0 | W9: 0 | X9: 0 | Y9: =Z9+AA9+AB9 -> 0 | Z9: 0 | AA9: 0 | AB9: 0 | AC9: 0 | AD9: 0 | AE9: 0 | AF9: 0 | AG9: =AG8+AD9-AE9-AF9 -> 6
A10: 45845 | B10: 월 | C10: 3 | D10: 2 | E10: 7 | F10: 4 | G10: 1 | H10: 2 | I10: =C10+D10+E10+F10+G10+H10 -> 19 | J10: 7 | K10: 5 | L10: =J10+K10 -> 12 | M10: 라벨 1 / 출고 4 | N10: 19 | P10: 7 | Q10: 5 | R10: 180 | S10: 풀필먼트출고 자동화 기기 고장 | T10: =U10+Z10 -> 8831 | U10: =V10+W10+X10 -> 6273 | V10: 0 | W10: 62 | X10: 6211 | Y10: =Z10+AA10+AB10 -> 4357 | Z10: 2558 | AA10: 140 | AB10: 1659 | AC10: 1 | AD10: 42 | AE10: 0 | AF10: 0 | AG10: =AG9+AD10-AE10-AF10 -> 48
A11: 45846 | B11: 화 | C11: 3 | D11: 2 | E11: 6 | F11: 5 | G11: 2 | H11: 2 | I11: =C11+D11+E11+F11+G11+H11 -> 20 | J11: 7 | K11: 5 | L11: =J11+K11 -> 12 | M11: 라벨 2 / 출고 3 | T11: =U11+Z11 -> 7640 | U11: =V11+W11+X11 -> 6624 | V11: 0 | W11: 66 | X11: 6558 | Y11: =Z11+AA11+AB11 -> 3367 | Z11: 1016 | AA11: 82 | AB11: 2269 | AC11: 4 | AD11: 79 | AE11: 44 | AF11: 1 | AG11: =AG10+AD11-AE11-AF11 -> 82
A12: 45847 | B12: 수 | C12: 3 | D12: 2 | E12: 6 | F12: 4 | G12: 2 | H12: 2 | I12: =C12+D12+E12+F12+G12+H12 -> 19 | J12: 6 | K12: 6 | L12: =J12+K12 -> 12 | M12: 라벨 3 / 출고 3 | T12: =U12+Z12 -> 7366 | U12: =V12+W12+X12 -> 6473 | V12: 0 | W12: 69 | X12: 6404 | Y12: =Z12+AA12+AB12 -> 2750 | Z12: 893 | AA12: 86 | AB12: 1771 | AC12: 14 | AD12: 80 | AE12: 0 | AF12: 1 | AG12: =AG11+AD12-AE12-AF12 -> 161
A13: 45848 | B13: 목 | C13: 3 | D13: 2 | E13: 5 | F13: 4 | G13: 2 | H13: 2 | I13: =C13+D13+E13+F13+G13+H13 -> 18 | J13: 7 | K13: 5 | L13: =J13+K13 -> 12 | M13: 라벨 2 / 출고 3 | T13: =U13+Z13 -> 6516 | U13: =V13+W13+X13 -> 5544 | V13: 0 | W13: 368 | X13: 5176 | Y13: =Z13+AA13+AB13 -> 2650 | Z13: 972 | AA13: 119 | AB13: 1559 | AC13: 1 | AD13: 14 | AE13: 0 | AF13: 0 | AG13: =AG12+AD13-AE13-AF13 -> 175
A14: 45849 | B14: 금 | C14: 3 | D14: 2 | E14: 5 | F14: 4 | G14: 2 | H14: 2 | I14: =C14+D14+E14+F14+G14+H14 -> 18 | J14: 6 | K14: 15 | L14: =J14+K14 -> 21 | M14: 라벨 12 / 출고 3 | T14: =U14+Z14 -> 5676 | U14: =V14+W14+X14 -> 4745 | V14: 0 | W14: 87 | X14: 4658 | Y14: =Z14+AA14+AB14 -> 2280 | Z14: 931 | AA14: 29 | AB14: 1320 | AC14: 1 | AD14: 28 | AE14: 173 | AF14: 0 | AG14: =AG13+AD14-AE14-AF14 -> 30
A15: 45850 | B15: 토 | C15: 0 | D15: 0 | E15: 0 | F15: 0 | G15: 0 | H15: 0 | I15: =C15+D15+E15+F15+G15+H15 -> 0 | J15: =M15+N15+P15 -> 0 | K15: =M15+N15+P15 -> 0 | L15: =J15+K15 -> 0 | T15: =U15+Z15 -> 0 | U15: =V15+W15+X15 -> 0 | V15: 0 | W15: 0 | X15: 0 | Y15: =Z15+AA15+AB15 -> 0 | Z15: 0 | AA15: 0 | AB15: 0 | AC15: 0 | AD15: 0 | AE15: 0 | AF15: 0 | AG15: =AG14+AD15-AE15-AF15 -> 30
A16: 45851 | B16: 일 | C16: 0 | D16: 0 | E16: 0 | F16: 0 | G16: 0 | H16: 0 | I16: =C16+D16+E16+F16+G16+H16 -> 0 | J16: =M16+N16+P16 -> 0 | K16: =M16+N16+P16 -> 0 | L16: =J16+K16 -> 0 | T16: =U16+Z16 -> 0 | U16: =V16+W16+X16 -> 0 | V16: 0 | W16: 0 | X16: 0 | Y16: =Z16+AA16+AB16 -> 0 | Z16: 0 | AA16: 0 | AB16: 0 | AC16: 0 | AD16: 0 | AE16: 0 | AF16: 0 | AG16: =AG15+AD16-AE16-AF16 -> 30
A17: 45852 | B17: 월 | C17: 3 | D17: 2 | E17: 6 | F17: 4 | G17: 2 | H17: 2 | I17: =C17+D17+E17+F17+G17+H17 -> 19 | J17: 7 | K17: 17 | L17: =J17+K17 -> 24 | M17: 라벨 12 / 출고 5 | T17: =U17+Z17 -> 8198 | U17: =V17+W17+X17 -> 5529 | V17: 0 | W17: 71 | X17: 5458 | Y17: =Z17+AA17+AB17 -> 3587 | Z17: 2669 | AA17: 71 | AB17: 847 | AC17: 5 | AD17: 47 | AE17: 0 | AF17: 0 | AG17: =AG16+AD17-AE17-AF17 -> 77
A18: 45853 | B18: 화 | C18: 3 | D18: 2 | E18: 6 | F18: 4 | G18: 2 | H18: 2 | I18: =C18+D18+E18+F18+G18+H18 -> 19 | J18: 7 | K18: 20 | L18: =J18+K18 -> 27 | M18: 라벨 15 / 출고 5 | T18: =U18+Z18 -> 6570 | U18: =V18+W18+X18 -> 5482 | V18: 0 | W18: 66 | X18: 5416 | Y18: =Z18+AA18+AB18 -> 3810 | Z18: 1088 | AA18: 46 | AB18: 2676 | AC18: 44 | AD18: 453 | AE18: 45 | AF18: 0 | AG18: =AG17+AD18-AE18-AF18 -> 485
A19: 45854 | B19: 수 | C19: 3 | D19: 2 | E19: 6 | F19: 4 | G19: 2 | H19: 2 | I19: =C19+D19+E19+F19+G19+H19 -> 19 | J19: 7 | K19: 14 | L19: =J19+K19 -> 21 | M19: 라벨 10 / 출고 4 | T19: =U19+Z19 -> 5478 | U19: =V19+W19+X19 -> 4242 | V19: 0 | W19: 62 | X19: 4180 | Y19: =Z19+AA19+AB19 -> 2564 | Z19: 1236 | AA19: 46 | AB19: 1282 | AC19: 3 | AD19: 42 | AE19: 0 | AF19: 3 | AG19: =AG18+AD19-AE19-AF19 -> 524
A20: 45855 | B20: 목 | C20: 3 | D20: 1 | E20: 5 | F20: 4 | G20: 2 | H20: 2 | I20: =C20+D20+E20+F20+G20+H20 -> 17 | J20: 7 | K20: 5 | L20: =J20+K20 -> 12 | M20: 라벨 2 / 출고 3 | T20: =U20+Z20 -> 3823 | U20: =V20+W20+X20 -> 2895 | V20: 0 | W20: 82 | X20: 2813 | Y20: =Z20+AA20+AB20 -> 1679 | Z20: 928 | AA20: 28 | AB20: 723 | AC20: 3 | AD20: 233 | AE20: 0 | AF20: 0 | AG20: =AG19+AD20-AE20-AF20 -> 757
A21: 45856 | B21: 금 | C21: 3 | D21: 1 | E21: 4 | F21: 3 | G21: 2 | H21: 2 | I21: =C21+D21+E21+F21+G21+H21 -> 15 | J21: 5 | K21: 5 | L21: =J21+K21 -> 10 | M21: 라벨 3 / 출고 2 | T21: =U21+Z21 -> 3613 | U21: =V21+W21+X21 -> 2628 | V21: 0 | W21: 60 | X21: 2568 | Y21: =Z21+AA21+AB21 -> 1826 | Z21: 985 | AA21: 38 | AB21: 803 | AC21: 25 | AD21: 371 | AE21: 755 | AF21: 0 | AG21: =AG20+AD21-AE21-AF21 -> 373
A22: 45857 | B22: 토 | C22: 0 | D22: 0 | E22: 0 | F22: 0 | G22: 0 | H22: 0 | I22: =C22+D22+E22+F22+G22+H22 -> 0 | J22: 0 | K22: 0 | L22: =J22+K22 -> 0 | T22: =U22+Z22 -> 0 | U22: =V22+W22+X22 -> 0 | V22: 0 | W22: 0 | X22: 0 | Y22: =Z22+AA22+AB22 -> 0 | Z22: 0 | AA22: 0 | AB22: 0 | AC22: 0 | AD22: 0 | AE22: 0 | AF22: 0 | AG22: =AG21+AD22-AE22-AF22 -> 373
A23: 45858 | B23: 일 | C23: 0 | D23: 0 | E23: 0 | F23: 0 | G23: 0 | H23: 0 | I23: =C23+D23+E23+F23+G23+H23 -> 0 | J23: 0 | K23: 0 | L23: =J23+K23 -> 0 | T23: =U23+Z23 -> 0 | U23: =V23+W23+X23 -> 0 | V23: 0 | W23: 0 | X23: 0 | Y23: =Z23+AA23+AB23 -> 0 | Z23: 0 | AA23: 0 | AB23: 0 | AC23: 0 | AD23: 0 | AE23: 0 | AF23: 0 | AG23: =AG22+AD23-AE23-AF23 -> 373
A24: 45859 | B24: 월 | C24: 3 | D24: 2 | E24: 7 | F24: 4 | G24: 2 | H24: 2 | I24: =C24+D24+E24+F24+G24+H24 -> 20 | J24: 6 | K24: 5 | L24: =J24+K24 -> 11 | M24: 출고 5 | N24: 2 | R24: 90 | S24: 전산 업무 | T24: =U24+Z24 -> 6430 | U24: =V24+W24+X24 -> 3503 | V24: 0 | W24: 63 | X24: 3440 | Y24: =Z24+AA24+AB24 -> 3649 | Z24: 2927 | AA24: 78 | AB24: 644 | AC24: 4 | AD24: 400 | AE24: 0 | AF24: 0 | AG24: =AG23+AD24-AE24-AF24 -> 773
A25: 45860 | B25: 화 | C25: 2 | D25: 2 | E25: 7 | F25: 4 | G25: 2 | H25: 2 | I25: =C25+D25+E25+F25+G25+H25 -> 19 | J25: 6 | K25: 4 | L25: =J25+K25 -> 10 | M25: 출고4 | N25: 9 | P25: 2 | Q25: 1 | R25: 90 | S25: ops 테스트 | T25: =U25+Z25 -> 5908 | U25: =V25+W25+X25 -> 4902 | V25: 0 | W25: 45 | X25: 4857 | Y25: =Z25+AA25+AB25 -> 2837 | Z25: 1006 | AA25: 8 | AB25: 1823 | AC25: 21 | AD25: 34 | AE25: 388 | AF25: 0 | AG25: =AG24+AD25-AE25-AF25 -> 419
A26: 45861 | B26: 수 | C26: 3 | D26: 2 | E26: 7 | F26: 3 | G26: 2 | H26: 2 | I26: =C26+D26+E26+F26+G26+H26 -> 19 | J26: 6.5 | K26: 12 | L26: =J26+K26 -> 18.5 | M26: 라벨 9 / 출고 3 | T26: =U26+Z26 -> 4377 | U26: =V26+W26+X26 -> 3419 | V26: 0 | W26: 55 | X26: 3364 | Y26: =Z26+AA26+AB26 -> 2162 | Z26: 958 | AA26: 16 | AB26: 1188 | AC26: 5 | AD26: 83 | AE26: 0 | AF26: 0 | AG26: =AG25+AD26-AE26-AF26 -> 502
A27: 45862 | B27: 목 | C27: 3 | D27: 1 | E27: 7 | F27: 4 | G27: 2 | H27: 2 | I27: =C27+D27+E27+F27+G27+H27 -> 19 | J27: 7 | K27: 12 | L27: =J27+K27 -> 19 | M27: 라벨 9 / 출고 3 | T27: =U27+Z27 -> 3602 | U27: =V27+W27+X27 -> 2698 | V27: 0 | W27: 44 | X27: 2654 | Y27: =Z27+AA27+AB27 -> 1629 | Z27: 904 | AA27: 6 | AB27: 719 | AC27: 33 | AD27: 89 | AE27: 464 | AF27: 0 | AG27: =AG26+AD27-AE27-AF27 -> 127
A28: 45863 | B28: 금 | C28: 3 | D28: 2 | E28: 6 | F28: 3 | G28: 1 | H28: 2 | I28: =C28+D28+E28+F28+G28+H28 -> 17 | J28: 6 | K28: 2 | L28: =J28+K28 -> 8 | M28: 출고 2 | T28: =U28+Z28 -> 3862 | U28: =V28+W28+X28 -> 3024 | V28: 0 | W28: 59 | X28: 2965 | Y28: =Z28+AA28+AB28 -> 1583 | Z28: 838 | AA28: 17 | AB28: 728 | AC28: 6 | AD28: 568 | AE28: 500 | AF28: 0 | AG28: =AG27+AD28-AE28-AF28 -> 195
A29: 45864 | B29: 토 | C29: 0 | D29: 0 | E29: 1 | F29: 1 | G29: 0 | H29: 0 | I29: =C29+D29+E29+F29+G29+H29 -> 2 | J29: 0 | K29: 0 | L29: =J29+K29 -> 0 | T29: =U29+Z29 -> 67 | U29: =V29+W29+X29 -> 67 | V29: 0 | W29: 0 | X29: 67 | Y29: =Z29+AA29+AB29 -> 67 | Z29: 0 | AA29: 0 | AB29: 67 | AC29: 0 | AD29: 0 | AE29: 0 | AF29: 0 | AG29: =AG28+AD29-AE29-AF29 -> 195
A30: 45865 | B30: 일 | C30: 0 | D30: 0 | E30: 1 | F30: 1 | G30: 0 | H30: 0 | I30: =C30+D30+E30+F30+G30+H30 -> 2 | J30: 0 | K30: 0 | L30: =J30+K30 -> 0 | T30: =U30+Z30 -> 68 | U30: =V30+W30+X30 -> 68 | V30: 0 | W30: 0 | X30: 68 | Y30: =Z30+AA30+AB30 -> 68 | Z30: 0 | AA30: 0 | AB30: 68 | AC30: 0 | AD30: 0 | AE30: 0 | AF30: 0 | AG30: =AG29+AD30-AE30-AF30 -> 195
A31: 45866 | B31: 월 | C31: 3 | D31: 2 | E31: 6 | F31: 4 | G31: 2 | H31: 2 | I31: =C31+D31+E31+F31+G31+H31 -> 19 | J31: 7 | K31: 4 | L31: =J31+K31 -> 11 | M31: 출고 4 | T31: =U31+Z31 -> 6453 | U31: =V31+W31+X31 -> 4041 | V31: 0 | W31: 70 | X31: 3971 | Y31: =Z31+AA31+AB31 -> 3107 | Z31: 2412 | AA31: 68 | AB31: 627 | AC31: 1 | AD31: 204 | AE31: 0 | AF31: 0 | AG31: =AG30+AD31-AE31-AF31 -> 399
A32: 45867 | B32: 화 | C32: 3 | D32: 2 | E32: 6 | F32: 4 | G32: 2 | H32: 2 | I32: =C32+D32+E32+F32+G32+H32 -> 19 | J32: 6.5 | K32: 3 | L32: =J32+K32 -> 9.5 | M32: 출고 3 | T32: =U32+Z32 -> 6253 | U32: =V32+W32+X32 -> 5229 | V32: 0 | W32: 83 | X32: 5146 | Y32: =Z32+AA32+AB32 -> 2950 | Z32: 1024 | AA32: 56 | AB32: 1870 | AC32: 1 | AD32: 261 | AE32: 395 | AF32: 2 | AG32: =AG31+AD32-AE32-AF32 -> 263
A33: 45868 | B33: 수 | C33: 3 | D33: 2 | E33: 7 | F33: 3 | G33: 1 | H33: 2 | I33: =C33+D33+E33+F33+G33+H33 -> 18 | J33: 7 | K33: 2 | L33: =J33+K33 -> 9 | M33: 출고 2 | N33: 1 | R33: 150 | S33: VTPL_B2B작업 | T33: =U33+Z33 -> 4924 | U33: =V33+W33+X33 -> 4038 | V33: 0 | W33: 65 | X33: 3973 | Y33: =Z33+AA33+AB33 -> 1570 | Z33: 886 | AA33: 35 | AB33: 649 | AC33: 3 | AD33: 106 | AE33: 0 | AF33: 0 | AG33: =AG32+AD33-AE33-AF33 -> 369
A34: 45869 | B34: 목 | C34: 3 | D34: 2 | E34: 7 | F34: 3 | G34: 1 | H34: 2 | I34: =C34+D34+E34+F34+G34+H34 -> 18 | J34: 7 | K34: 2 | L34: =J34+K34 -> 9 | M34: 출고 2 | T34: =U34+Z34 -> 3888 | U34: =V34+W34+X34 -> 2835 | V34: 0 | W34: 26 | X34: 2809 | Y34: =Z34+AA34+AB34 -> 1621 | Z34: 1053 | AA34: 9 | AB34: 559 | AC34: 14 | AD34: 66 | AE34: 366 | AF34: 1 | AG34: =AG33+AD34-AE34-AF34 -> 68
A35: 합계 | C35: =SUM(C4:C34) -> 67 | D35: =SUM(D4:D34) -> 42.5 | E35: =SUM(E4:E34) -> 145 | F35: =SUM(F4:F34) -> 89 | G35: =SUM(G4:G34) -> 42 | H35: =SUM(H4:H34) -> 46 | I35: =SUM(I4:I34) -> 431.5 | J35: =SUM(J4:J34) -> 150.5 | ... L35: =SUM(L4:L34) -> 304.5 | N35: =SUM(N4:N34) -> 51 | P35: =SUM(P4:P34) -> 15 | Q35: =SUM(Q4:Q34) -> 9 | R35: =SUM(R4:R34) -> 810 | T35: =SUM(T4:T34) -> 135514 | U35: =SUM(U4:U34) -> 106633 | V35: =SUM(V4:V34) -> 0 | W35: =SUM(W4:W34) -> 1700 | X35: =SUM(X4:X34) -> 104933 | Y35: =SUM(Y4:Y34) -> 59743 | Z35: =SUM(Z4:Z34) -> 28881 | AA35: =SUM(AA4:AA34) -> 1219 | ... AF35: =SUM(AF4:AF34) -> 8
A36: ▣ 참고사항 (단기 충원 사유)
A37: ① OPS 단기 1명 고정 투입 중(입고 홍순호과장 퇴사 후 OPS 김필재대리 입고파트로 전환 배치 후 정직원이 아닌 단기 인력 투입)
A38: ② 월, 화 VTPL 출고 화물 (15시 기준) 당일 출고 (1~2명)
A39: ③ VTPL 국내 행사 사전 공유 시 1~2명 투입
A40: ④ B2B 출고 요청 작업 발생 시
...

Sheet 8월
A1: 일자 | B1: 요일 | J1: 운영 근무자 잔업 | P1: 영종ALL | Q1: OPS 출하건수 | U1: WMS 작업건수 | Y1: B2B | Z1: WMG | AD1: 비고
C2: 정직원 | F2: 협력사원 | I2: 단기충원사유
C3: OPS, QFC | D3: 마곡지원 | E3: 합계 | F3: 장기협력사원 | G3: 단기협력사원 | H3: 합계 | J3: OPS, QFC | K3: 에러,입고,픽업 | L3: 장기협력사원 | M3: 단기협력사원 | N3: 잔업시간(분) | O3: 잔업사유 | P3: ALL | Q3: KR-All | R3: KRKR | S3: KR-Oversea | T3: KRJP | U3: KR-All | V3: KRKR | W3: KR-Oversea | X3: KRJP | Y3: 출고 건수 | Z3: 입고건수 | AA3: 출고건수 | AB3: 반송 | AC3: 미출고
A4: 45870 | B4: 금 | C4: 18 | D4: 0 | E4: =C4+D4 -> 18 | F4: 7 | G4: 1 | H4: =F4+G4 -> 8 | I4: 출고 1 | J4: 5 | N4: 90 | O4: 풀필먼트 출고 | P4: =Q4+V4 -> 5294 | Q4: =R4+S4+T4 -> 4326 | R4: 0 | S4: 53 | T4: 4273 | U4: =V4+W4+X4 -> 2175 | V4: 968 | W4: 89 | X4: 1118 | Y4: 1 | Z4: 53 | AA4: 119 | AB4: 0 | AC4: =68+Z4-AA4-AB4 -> 2
A5: 45871 | B5: 토 | C5: 11 | D5: 0 | E5: =C5+D5 -> 11 | F5: 0 | G5: 0 | H5: =F5+G5 -> 0 | P5: =Q5+V5 -> 164 | Q5: =R5+S5+T5 -> 164 | R5: 0 | S5: 0 | T5: 164 | U5: =V5+W5+X5 -> 164 | V5: 0 | W5: 0 | X5: 164 | Y5: 0 | Z5: 0 | AA5: 0 | AB5: 0 | AC5: =AC4+Z5-AA5-AB5 -> 2
A6: 45872 | B6: 일 | C6: 3 | D6: 0 | E6: =C6+D6 -> 3 | F6: 0 | G6: 0 | H6: =F6+G6 -> 0 | P6: =Q6+V6 -> 178 | Q6: =R6+S6+T6 -> 178 | R6: 0 | S6: 0 | T6: 178 | U6: =V6+W6+X6 -> 178 | V6: 0 | W6: 0 | X6: 178 | Y6: 0 | Z6: 0 | AA6: 0 | AB6: 0 | AC6: =AC5+Z6-AA6-AB6 -> 2
A7: 45873 | B7: 월 | C7: 17 | D7: 0 | E7: =C7+D7 -> 17 | F7: 6 | G7: 2 | H7: =F7+G7 -> 8 | I7: 출고 2 | J7: 15 | L7: 4 | M7: 3 | N7: 180 | O7: 풀필먼트출고/twms멀티패턴시스템오류 | P7: =Q7+V7 -> 8680 | Q7: =R7+S7+T7 -> 5919 | R7: 0 | S7: 22 | T7: 5897 | U7: =V7+W7+X7 -> 3380 | V7: 2761 | W7: 78 | X7: 541 | Y7: 23 | Z7: 23 | AA7: 0 | AB7: 0 | AC7: =AC6+Z7-AA7-AB7 -> 25
A8: 45874 | B8: 화 | C8: 18 | D8: 0 | E8: =C8+D8 -> 18 | F8: 7 | G8: 5 | H8: =F8+G8 -> 12 | I8: 출고 5 | J8: 16 | L8: 5 | M8: 3 | N8: 180 | O8: 풀필먼트 출고 / ops 출고 | P8: =Q8+V8 -> 13123 | Q8: =R8+S8+T8 -> 11827 | R8: 0 | S8: 57 | T8: 11770 | U8: =V8+W8+X8 -> 3965 | V8: 1296 | W8: 44 | X8: 2625 | Y8: 3 | Z8: 4 | AA8: 0 | AB8: 0 | AC8: =AC7+Z8-AA8-AB8 -> 29
A9: 45875 | B9: 수 | C9: 17 | D9: 14 | E9: =C9+D9 -> 31 | F9: 7 | G9: 1 | H9: =F9+G9 -> 8 | I9: 출고 1 | J9: 15 | L9: 2 | M9: 1 | N9: 180 | O9: 풀필먼트 출고 / ops 출고 | P9: =Q9+V9 -> 11803 | Q9: =R9+S9+T9 -> 10735 | R9: 0 | S9: 85 | T9: 10650 | U9: =V9+W9+X9 -> 3803 | V9: 1068 | W9: 66 | X9: 2669 | Y9: 36 | Z9: 0 | AA9: 27 | AB9: 0 | AC9: =AC8+Z9-AA9-AB9 -> 2
A10: 45876 | B10: 목 | C10: 16 | D10: 10 | E10: =C10+D10 -> 26 | F10: 7 | G10: 1 | H10: =F10+G10 -> 8 | I10: 출고 1 | J10: 15 | L10: 1 | M10: 1 | N10: 90 | O10: 풀필먼트 출고 / ops 출고 | P10: =Q10+V10 -> 6045 | Q10: =R10+S10+T10 -> 5152 | R10: 0 | S10: 20 | T10: 5132 | U10: =V10+W10+X10 -> 2898 | V10: 893 | W10: 6 | X10: 1999 | Y10: 25 | Z10: 291 | AA10: 0 | AB10: 1 | AC10: =AC9+Z10-AA10-AB10 -> 292
A11: 45877 | B11: 금 | C11: 16 | D11: 6 | E11: =C11+D11 -> 22 | F11: 6 | G11: 4 | H11: =F11+G11 -> 10 | I11: 출고4 | N11: 60 | O11: OPS출고 | P11: =Q11+V11 -> 7496 | Q11: =R11+S11+T11 -> 6655 | R11: 0 | S11: 65 | T11: 6590 | U11: =V11+W11+X11 -> 2673 | V11: 841 | W11: 43 | X11: 1789 | Y11: 25 | Z11: 95 | AA11: 290 | AB11: 0 | AC11: =AC10+Z11-AA11-AB11 -> 97
A12: 45878 | B12: 토 | C12: 2 | D12: 0 | E12: =C12+D12 -> 2 | F12: 0 | G12: 0 | H12: =F12+G12 -> 0 | P12: =Q12+V12 -> 188 | Q12: =R12+S12+T12 -> 188 | R12: 0 | S12: 6 | T12: 182 | U12: =V12+W12+X12 -> 187 | V12: 0 | W12: 6 | X12: 181 | Y12: 0 | Z12: 0 | AA12: 0 | AB12: 0 | AC12: =AC11+Z12-AA12-AB12 -> 97
A13: 45879 | B13: 일 | C13: 2 | D13: 0 | E13: =C13+D13 -> 2 | F13: 0 | G13: 0 | H13: =F13+G13 -> 0 | P13: =Q13+V13 -> 154 | Q13: =R13+S13+T13 -> 154 | R13: 0 | S13: 0 | T13: 154 | U13: =V13+W13+X13 -> 148 | V13: 0 | W13: 0 | X13: 148 | Y13: 0 | Z13: 0 | AA13: 0 | AB13: 0 | AC13: =AC12+Z13-AA13-AB13 -> 97
A14: 45880 | B14: 월 | C14: 17 | D14: 0 | E14: =C14+D14 -> 17 | F14: 6 | G14: 2 | H14: =F14+G14 -> 8 | I14: 출고 2 | J14: 15 | L14: 2 | M14: 2 | N14: 90 | O14: 풀필먼트 출고 | P14: =Q14+V14 -> 8086 | Q14: =R14+S14+T14 -> 5596 | R14: 0 | S14: 68 | T14: 5528 | U14: =V14+W14+X14 -> 3226 | V14: 2490 | W14: 189 | X14: 547 | Y14: 7 | Z14: 80 | AA14: 0 | AB14: 0 | AC14: =AC13+Z14-AA14-AB14 -> 177
A15: 45881 | B15: 화 | C15: 17 | D15: 7 | E15: =C15+D15 -> 24 | F15: 3 | G15: 7 | H15: =F15+G15 -> 10 | I15: 출고 7 | P15: =Q15+V15 -> 8736 | Q15: =R15+S15+T15 -> 7653 | R15: 0 | S15: 53 | T15: 7600 | U15: =V15+W15+X15 -> 2582 | V15: 1083 | W15: 20 | X15: 1479 | Y15: 52 | Z15: 94 | AA15: 0 | AB15: 0 | AC15: =AC14+Z15-AA15-AB15 -> 271
A16: 45882 | B16: 수 | C16: 16 | D16: 0 | E16: =C16+D16 -> 16 | F16: 4 | G16: 6 | H16: =F16+G16 -> 10 | I16: 출고 5 / 라벨 1 | J16: 13 | L16: 4 | M16: 1 | N16: 90 | O16: 풀필먼트 출고 / ops 출고 | P16: =Q16+V16 -> 7229 | Q16: =R16+S16+T16 -> 6257 | R16: 0 | S16: 42 | T16: 6215 | U16: =V16+W16+X16 -> 2530 | V16: 972 | W16: 81 | X16: 1477 | Y16: 48 | Z16: 321 | AA16: 269 | AB16: 0 | AC16: =AC15+Z16-AA16-AB16 -> 323
A17: 45883 | B17: 목 | C17: 15 | D17: 0 | E17: =C17+D17 -> 15 | F17: 4 | G17: 3 | H17: =F17+G17 -> 7 | I17: 출고 2 / 라벨 1 | J17: 6 | L17: 0 | M17: 0 | N17: 120 | O17: 풀필먼트 출고 | P17: =Q17+V17 -> 4050 | Q17: =R17+S17+T17 -> 3163 | R17: 0 | S17: 41 | T17: 3122 | U17: =V17+W17+X17 -> 1769 | V17: 887 | W17: 44 | X17: 838 | Y17: 38 | Z17: 202 | AA17: 0 | AB17: 0 | AC17: =AC16+Z17-AA17-AB17 -> 525
A18: 45884 | B18: 금 | C18: 6 | D18: 0 | E18: =C18+D18 -> 6 | F18: 0 | G18: 0 | H18: =F18+G18 -> 0 | P18: =Q18+V18 -> 341 | Q18: =R18+S18+T18 -> 341 | R18: 0 | S18: 0 | T18: 341 | U18: =V18+W18+X18 -> 176 | V18: 0 | W18: 0 | X18: 176 | Y18: 0 | Z18: 0 | AA18: 0 | AB18: 0 | AC18: =AC17+Z18-AA18-AB18 -> 525
A19: 45885 | B19: 토 | C19: 2 | D19: 0 | E19: =C19+D19 -> 2 | F19: 0 | G19: 0 | H19: =F19+G19 -> 0 | P19: =Q19+V19 -> 323 | Q19: =R19+S19+T19 -> 142 | R19: 0 | S19: 0 | T19: 142 | U19: =V19+W19+X19 -> 323 | V19: 181 | W19: 0 | X19: 142 | Y19: 0 | Z19: 0 | AA19: 0 | AB19: 0 | AC19: =AC18+Z19-AA19-AB19 -> 525
A20: 45886 | B20: 일 | C20: 2 | D20: 0 | E20: =C20+D20 -> 2 | F20: 0 | G20: 0 | H20: =F20+G20 -> 0 | P20: =Q20+V20 -> 248 | Q20: =R20+S20+T20 -> 248 | R20: 0 | S20: 0 | T20: 248 | U20: =V20+W20+X20 -> 248 | V20: 0 | W20: 0 | X20: 248 | Y20: 0 | Z20: 0 | AA20: 0 | AB20: 0 | AC20: =AC19+Z20-AA20-AB20 -> 525
A21: 45887 | B21: 월 | C21: 15 | D21: 0 | E21: =C21+D21 -> 15 | F21: 3 | G21: 1 | H21: =F21+G21 -> 4 | I21: 출고 1 | J21: 12 | L21: 3 | M21: 1 | N21: 180 | O21: 풀필먼트 출고 / ops 출고 | P21: =Q21+V21 -> 5913 | Q21: =R21+S21+T21 -> 2992 | R21: 0 | S21: 7 | T21: 2985 | U21: =V21+W21+X21 -> 3297 | V21: 2921 | W21: 322 | X21: 54 | Y21: 55 | Z21: 156 | AA21: 0 | AB21: 0 | AC21: =AC20+Z21-AA21-AB21 -> 681
A22: 45888 | B22: 화 | C22: 17 | D22: 0 | E22: =C22+D22 -> 17 | F22: 4 | G22: 4 | H22: =F22+G22 -> 8 | I22: 출고 4 | J22: 14 | L22: 0 | M22: 0 | N22: 90 | O22: 풀필먼트 출고 / ops 출고 | P22: =Q22+V22 -> 5865 | Q22: =R22+S22+T22 -> 4912 | R22: 0 | S22: 67 | T22: 4845 | U22: =V22+W22+X22 -> 2823 | V22: 953 | W22: 6 | X22: 1864 | Y22: 16 | Z22: 63 | AA22: 680 | AB22: 0 | AC22: =AC21+Z22-AA22-AB22 -> 64
A23: 45889 | B23: 수 | C23: 18 | D23: 0 | E23: =C23+D23 -> 18 | F23: 4 | G23: 3 | H23: =F23+G23 -> 7 | I23: 출고 3 | P23: =Q23+V23 -> 5182 | Q23: =R23+S23+T23 -> 4418 | R23: 0 | S23: 118 | T23: 4300 | U23: =V23+W23+X23 -> 1215 | V23: 764 | W23: 132 | X23: 319 | Y23: 8 | Z23: 76 | AA23: 0 | AB23: 0 | AC23: =AC22+Z23-AA23-AB23 -> 140
A24: 45890 | B24: 목 | C24: 18 | D24: 5 | E24: =C24+D24 -> 23 | F24: 4 | G24: 1 | H24: =F24+G24 -> 5 | I24: 출고 1 | J24: 2 | L24: 0 | M24: 0 | N24: 90 | O24: WMG 작업 | P24: =Q24+V24 -> 3625 | Q24: =R24+S24+T24 -> 2790 | R24: 0 | S24: 30 | T24: 2760 | U24: =V24+W24+X24 -> 1372 | V24: 835 | W24: 1 | X24: 536 | Y24: 28 | Z24: 117 | AA24: 0 | AB24: 0 | AC24: =AC23+Z24-AA24-AB24 -> 257
A25: 45891 | B25: 금 | C25: 18 | D25: 0 | E25: =C25+D25 -> 18 | F25: 4 | G25: 6 | H25: =F25+G25 -> 10 | I25: 출고 4 / 라벨 2 | P25: =Q25+V25 -> 4864 | Q25: =R25+S25+T25 -> 4097 | R25: 0 | S25: 92 | T25: 4005 | U25: =V25+W25+X25 -> 1899 | V25: 767 | W25: 113 | X25: 1019 | Y25: 31 | Z25: 30 | AA25: 257 | AB25: 0 | AC25: =AC24+Z25-AA25-AB25 -> 30
A26: 45892 | B26: 토 | C26: 2 | D26: 0 | E26: =C26+D26 -> 2 | F26: 0 | G26: 0 | H26: =F26+G26 -> 0 | P26: =Q26+V26 -> 212 | Q26: =R26+S26+T26 -> 136 | R26: 0 | S26: 0 | T26: 136 | U26: =V26+W26+X26 -> 212 | V26: 76 | W26: 0 | X26: 136 | Y26: 0 | Z26: 0 | AA26: 0 | AB26: 0 | AC26: =AC25+Z26-AA26-AB26 -> 30
A27: 45893 | B27: 일 | C27: 2 | D27: 0 | E27: =C27+D27 -> 2 | F27: 0 | G27: 0 | H27: =F27+G27 -> 0 | P27: =Q27+V27 -> 168 | Q27: =R27+S27+T27 -> 168 | R27: 0 | S27: 0 | T27: 168 | U27: =V27+W27+X27 -> 168 | V27: 0 | W27: 0 | X27: 168 | Y27: 0 | Z27: 0 | AA27: 0 | AB27: 0 | AC27: =AC26+Z27-AA27-AB27 -> 30
A28: 45894 | B28: 월 | C28: 16 | D28: 0 | E28: =C28+D28 -> 16 | F28: 3 | G28: 6 | H28: =F28+G28 -> 9 | I28: 출고 4 / 라벨 2 | J28: 4 | L28: 1 | M28: 3 | N28: 90 | O28: 풀필먼트 출고 | P28: =Q28+V28 -> 6632 | Q28: =R28+S28+T28 -> 4361 | R28: 0 | S28: 58 | T28: 4303 | U28: =V28+W28+X28 -> 2591 | V28: 2271 | W28: 21 | X28: 299 | Y28: 96 | Z28: 78 | AA28: 0 | AB28: 0 | AC28: =AC27+Z28-AA28-AB28 -> 108
A29: 45895 | B29: 화 | C29: 17 | D29: 0 | E29: =C29+D29 -> 17 | F29: 4 | G29: 11 | H29: =F29+G29 -> 15 | I29: 출고 11 | P29: =Q29+V29 -> 4764 | Q29: =R29+S29+T29 -> 3764 | R29: 0 | S29: 10 | T29: 3754 | U29: =V29+W29+X29 -> 2941 | V29: 1000 | W29: 154 | X29: 1787 | Y29: 93 | Z29: 99 | AA29: 0 | AB29: 0 | AC29: =AC28+Z29-AA29-AB29 -> 207
A30: 45896 | B30: 수 | C30: 16 | D30: 0 | E30: =C30+D30 -> 16 | F30: 4 | G30: 12 | H30: =F30+G30 -> 16 | I30: 출고 6 / 라벨 6 | P30: =Q30+V30 -> 7003 | Q30: =R30+S30+T30 -> 6087 | R30: 0 | S30: 71 | T30: 6016 | U30: =V30+W30+X30 -> 1879 | V30: 916 | W30: 159 | X30: 804 | Y30: 90 | Z30: 57 | AA30: 204 | AB30: 0 | AC30: =AC29+Z30-AA30-AB30 -> 60
A31: 45897 | B31: 목 | C31: 17 | D31: 0 | E31: =C31+D31 -> 17 | F31: 4 | G31: 10 | H31: =F31+G31 -> 14 | I31: 출고 4 / 라벨 6 | P31: =Q31+V31 -> 5425 | Q31: =R31+S31+T31 -> 4608 | R31: 0 | S31: 48 | T31: 4560 | U31: =V31+W31+X31 -> 2031 | V31: 817 | W31: 8 | X31: 1206 | Y31: 95 | Z31: 87 | AA31: 0 | AB31: 0 | AC31: =AC30+Z31-AA31-AB31 -> 147
A32: 45898 | B32: 금 | C32: 13.5 | D32: 0 | E32: =C32+D32 -> 13.5 | F32: 4 | G32: 14 | H32: =F32+G32 -> 18 | I32: 출고 10 / 라벨 4 | P32: =Q32+V32 -> 6172 | Q32: =R32+S32+T32 -> 5506 | R32: 0 | S32: 40 | T32: 5466 | U32: =V32+W32+X32 -> 2506 | V32: 666 | W32: 3 | X32: 1837 | Y32: 92 | Z32: 137 | AA32: 145 | AB32: 0 | AC32: =AC31+Z32-AA32-AB32 -> 139
A33: 45899 | B33: 토 | C33: 2 | D33: 0 | E33: =C33+D33 -> 2 | F33: 0 | G33: 0 | H33: =F33+G33 -> 0 | P33: =Q33+V33 -> 242 | Q33: =R33+S33+T33 -> 168 | R33: 0 | S33: 0 | T33: 168 | U33: =V33+W33+X33 -> 242 | V33: 74 | W33: 0 | X33: 168 | Y33: 0 | Z33: 0 | AA33: 0 | AB33: 0 | AC33: =AC32+Z33-AA33-AB33 -> 139
A34: 45900 | B34: 일 | C34: 2 | D34: 0 | E34: =C34+D34 -> 2 | F34: 0 | G34: 0 | H34: =F34+G34 -> 0 | P34: =Q34+V34 -> 487 | Q34: =R34+S34+T34 -> 487 | R34: 0 | S34: 0 | T34: 487 | U34: =V34+W34+X34 -> 456 | V34: 0 | W34: 0 | X34: 456 | Y34: 0 | Z34: 0 | AA34: 0 | AB34: 0 | AC34: =AC33+Z34-AA34-AB34 -> 139
A35: 합계 | C35: =SUM(C4:C34) -> 368.5 | D35: =SUM(D4:D34) -> 42 | E35: =SUM(E4:E34) -> 410.5 | F35: =SUM(F4:F34) -> 95 | G35: =SUM(G4:G34) -> 100 | H35: =SUM(H4:H34) -> 195 | J35: =SUM(J4:J34) -> 132 | L35: =SUM(L4:L34) -> 22 | M35: =SUM(M4:M34) -> 15 | N35: =SUM(N4:N34) -> 1530 | P35: =SUM(P4:P34) -> 138692 | Q35: =SUM(Q4:Q34) -> 113192 | R35: =SUM(R4:R34) -> 0 | S35: =SUM(S4:S34) -> 1053 | T35: =SUM(T4:T34) -> 112139 | U35: =SUM(U4:U34) -> 54057 | V35: =SUM(V4:V34) -> 25500 | W35: =SUM(W4:W34) -> 1585 | ... AB35: =SUM(AB4:AB34) -> 1
A36: ▣ 참고사항 (단기 충원 사유)
A37: ① OPS 단기 1명 고정 투입 중(입고 홍순호과장 퇴사 후 OPS 김필재대리 입고파트로 전환 배치 후 정직원이 아닌 단기 인력 투입)
A38: ② 월, 화 VTPL 출고 화물 (15시 기준) 당일 출고 (1~2명)
A39: ③ VTPL 국내 행사 사전 공유 시 1~2명 투입
A40: ④ B2B 출고 요청 작업 발생 시
...

Sheet 9월
A1: 일자 | B1: 요일 | L1: 운영 근무자 잔업 | R1: 영종ALL | S1: OPS 출하건수 | W1: WMS 작업건수 | AA1: B2B | AB1: WMG | AF1: 비고
C2: 정직원 | F2: 협력사원 | J2: 야간 | K2: 단기충원사유
C3: OPS, QFC | D3: 마곡지원 | E3: 합계 | F3: 장기협력사원 | G3: 단기협력사원 | H3: 직원단기 | I3: 합계 | J3: 단기협력사원 | L3: OPS, QFC | M3: 에러,입고,픽업 | N3: 장기협력사원 | O3: 단기협력사원 | P3: 잔업시간(분) | Q3: 잔업사유 | R3: ALL | S3: KR-All | T3: KRKR | U3: KR-Oversea | V3: KRJP | W3: KR-All | X3: KRKR | Y3: KR-Oversea | Z3: KRJP | AA3: 출고 건수 | AB3: 입고건수 | AC3: 출고건수 | AD3: 반송 | AE3: 미출고
A4: 45901 | B4: 월 | C4: 10 | D4: =4+5 -> 9 | E4: =C4+D4 -> 19 | F4: 5 | G4: 24 | H4: 0 | I4: =F4+G4+H4 -> 29 | J4: 0 | K4: 메가와리 출고 | L4: 9 | N4: 5 | O4: =3+4 -> 7 | P4: 120~300 | Q4: 메가와리 출고 | R4: =S4+X4 -> 20408 | S4: =T4+U4+V4 -> 18598 | T4: 0 | U4: 25 | V4: 18573 | W4: =X4+Y4+Z4 -> 6999 | X4: 1810 | Y4: 107 | Z4: 5082 | AA4: 91 | AB4: 105 | AC4: 0 | AD4: 0 | AE4: =139+AB4-AC4-AD4 -> 244
A5: 45902 | B5: 화 | C5: 10 | D5: 17 | E5: =C5+D5 -> 27 | F5: 5 | G5: 24 | H5: 0 | I5: =F5+G5+H5 -> 29 | J5: 0 | K5: 메가와리 출고 | L5: 9 | N5: 5 | O5: 8 | P5: 120~240 | Q5: 메가와리 출고 | R5: =S5+X5 -> 25165 | S5: =T5+U5+V5 -> 24550 | T5: 0 | U5: 18 | V5: 24532 | W5: =X5+Y5+Z5 -> 6861 | X5: 615 | Y5: 6 | Z5: 6240 | AA5: 91 | AB5: 131 | AC5: 0 | AD5: 0 | AE5: =AE4+AB5-AC5-AD5 -> 375
A6: 45903 | B6: 수 | C6: 10 | D6: 16 | E6: =C6+D6 -> 26 | F6: 5 | G6: 53.5 | H6: 0 | I6: =F6+G6+H6 -> 58.5 | J6: 16 | K6: 메가와리 출고 | L6: 9 | N6: 5 | O6: 15 | P6: 120~270 | Q6: 메가와리 출고 | R6: =S6+X6 -> 27174 | S6: =T6+U6+V6 -> 26241 | T6: 0 | U6: 0 | V6: 26241 | W6: =X6+Y6+Z6 -> 8105 | X6: 933 | Y6: 5 | Z6: 7167 | AA6: 93 | AB6: 124 | AC6: 372 | AD6: 0 | AE6: =AE5+AB6-AC6-AD6 -> 127
A7: 45904 | B7: 목 | C7: 9 | D7: 7 | E7: =C7+D7 -> 16 | F7: 5 | G7: 41 | H7: 2 | I7: =F7+G7+H7 -> 48 | J7: 9 | K7: 메가와리 출고 | L7: 9 | N7: 5 | O7: 11 | P7: 120~180 | Q7: 메가와리 출고 | R7: =S7+X7 -> 36884 | S7: =T7+U7+V7 -> 35672 | T7: 0 | U7: 62 | V7: 35610 | W7: =X7+Y7+Z7 -> 5838 | X7: 1212 | Y7: 6 | Z7: 4620 | AA7: 91 | AB7: 268 | AC7: 0 | AD7: 0 | AE7: =AE6+AB7-AC7-AD7 -> 395
A8: 45905 | B8: 금 | C8: 10 | D8: 13 | E8: =C8+D8 -> 23 | F8: 5 | G8: 29 | H8: 2 | I8: =F8+G8+H8 -> 36 | J8: 13 | K8: 메가와리 출고 | L8: 9 | N8: 5 | O8: 7 | P8: 120~450 | Q8: 메가와리 출고 | R8: =S8+X8 -> 29645 | S8: =T8+U8+V8 -> 28885 | T8: 0 | U8: 39 | V8: 28846 | W8: =X8+Y8+Z8 -> 5170 | X8: 760 | Y8: 7 | Z8: 4403 | AA8: 102 | AB8: 0 | AC8: 369 | AD8: 0 | AE8: =AE7+AB8-AC8-AD8 -> 26
A9: 45906 | B9: 토 | C9: 8 | D9: 8 | E9: =C9+D9 -> 16 | F9: 5 | G9: 15 | H9: 4 | I9: =F9+G9+H9 -> 24 | J9: 0 | K9: 메가와리 출고 | R9: =S9+X9 -> 21336 | S9: =T9+U9+V9 -> 21232 | T9: 0 | U9: 91 | V9: 21141 | W9: =X9+Y9+Z9 -> 2583 | X9: 104 | Y9: 193 | Z9: 2286 | AA9: 0 | AB9: 0 | AC9: 0 | AD9: 0 | AE9: =AE8+AB9-AC9-AD9 -> 26
A10: 45907 | B10: 일 | C10: 10 | D10: 8 | E10: =C10+D10 -> 18 | F10: 5 | G10: 17 | H10: 4 | I10: =F10+G10+H10 -> 26 | J10: 0 | K10: 메가와리 출고 | R10: =S10+X10 -> 21980 | S10: =T10+U10+V10 -> 21732 | T10: 0 | U10: 28 | V10: 21704 | W10: =X10+Y10+Z10 -> 3147 | X10: 248 | Y10: 141 | Z10: 2758 | AA10: 0 | AB10: 0 | AC10: 0 | AD10: 0 | AE10: =AE9+AB10-AC10-AD10 -> 26
A11: 45908 | B11: 월 | C11: 9.5 | D11: 5 | E11: =C11+D11 -> 14.5 | F11: 5 | G11: 41 | H11: 4 | I11: =F11+G11+H11 -> 50 | J11: 0 | K11: 메가와리 출고 | L11: 8 | N11: 5 | O11: 11 | P11: 120~180 | Q11: 메가와리 출고 | R11: =S11+X11 -> 37045 | S11: =T11+U11+V11 -> 34916 | T11: 0 | U11: 53 | V11: 34863 | W11: =X11+Y11+Z11 -> 5941 | X11: 2129 | Y11: 27 | Z11: 3785 | AA11: 96 | AB11: 196 | AC11: 0 | AD11: 0 | AE11: =AE10+AB11-AC11-AD11 -> 222
A12: 45909 | B12: 화 | C12: 10 | D12: 5 | E12: =C12+D12 -> 15 | F12: 5 | G12: 27 | H12: 4 | I12: =F12+G12+H12 -> 36 | J12: 0 | K12: 메가와리 출고 | L12: 9 | N12: 5 | O12: 11 | P12: 120~180 | Q12: 메가와리 출고 | R12: =S12+X12 -> 18919 | S12: =T12+U12+V12 -> 17795 | T12: 0 | U12: 16 | V12: 17779 | W12: =X12+Y12+Z12 -> 6570 | X12: 1124 | Y12: 34 | Z12: 5412 | AA12: 117 | AB12: 49 | AC12: 0 | AD12: 0 | AE12: =AE11+AB12-AC12-AD12 -> 271
A13: 45910 | B13: 수 | C13: 10 | D13: 4 | E13: =C13+D13 -> 14 | F13: 5 | G13: 29 | H13: 2 | I13: =F13+G13+H13 -> 36 | J13: 0 | K13: 메가와리 출고 | L13: 9 | N13: 5 | O13: 7 | P13: 120~180 | Q13: 메가와리 출고 | R13: =S13+X13 -> 27643 | S13: =T13+U13+V13 -> 26516 | T13: 0 | U13: 53 | V13: 26463 | W13: =X13+Y13+Z13 -> 4161 | X13: 1127 | Y13: 46 | Z13: 2988 | AA13: 4 | AB13: 98 | AC13: 343 | AD13: 0 | AE13: =AE12+AB13-AC13-AD13 -> 26
A14: 45911 | B14: 목 | C14: 10 | D14: 3 | E14: =C14+D14 -> 13 | F14: 5 | G14: 15 | H14: 2 | I14: =F14+G14+H14 -> 22 | J14: 0 | K14: 메가와리 출고 | L14: 9 | N14: 4 | O14: 2 | P14: 120~180 | Q14: 메가와리 출고 | R14: =S14+X14 -> 23650 | S14: =T14+U14+V14 -> 22598 | T14: 0 | U14: 35 | V14: 22563 | W14: =X14+Y14+Z14 -> 2815 | X14: 1052 | Y14: 35 | Z14: 1728 | AA14: 6 | AB14: 126 | AC14: 0 | AD14: 0 | AE14: =AE13+AB14-AC14-AD14 -> 152
A15: 45912 | B15: 금 | C15: 12 | D15: 2 | E15: =C15+D15 -> 14 | F15: 5 | G15: 24 | H15: 2 | I15: =F15+G15+H15 -> 31 | J15: 0 | K15: 메가와리 출고 / 라벨 2 | L15: 9 | N15: 5 | O15: 14 | P15: 120 | Q15: 메가와리 출고 | R15: =S15+X15 -> 29349 | S15: =T15+U15+V15 -> 27674 | T15: 0 | U15: 46 | V15: 27628 | W15: =X15+Y15+Z15 -> 3403 | X15: 1675 | Y15: 13 | Z15: 1715 | AA15: 1 | AB15: 72 | AC15: 123 | AD15: 0 | AE15: =AE14+AB15-AC15-AD15 -> 101
A16: 45913 | B16: 토 | C16: 10 | D16: 2 | E16: =C16+D16 -> 12 | F16: 5 | G16: 7 | H16: 0 | I16: =F16+G16+H16 -> 12 | J16: 0 | K16: 메가와리 출고 | R16: =S16+X16 -> 19136 | S16: =T16+U16+V16 -> 19136 | T16: 0 | U16: 23 | V16: 19113 | W16: =X16+Y16+Z16 -> 2203 | X16: 0 | Y16: 1 | Z16: 2202 | AA16: 0 | AB16: 0 | AC16: 0 | AD16: 0 | AE16: =AE15+AB16-AC16-AD16 -> 101
A17: 45914 | B17: 일 | C17: 10 | D17: 0 | E17: =C17+D17 -> 10 | F17: 3 | G17: 15 | H17: 0 | I17: =F17+G17+H17 -> 18 | J17: 0 | K17: 메가와리 출고 | R17: =S17+X17 -> 20505 | S17: =T17+U17+V17 -> 20370 | T17: 0 | U17: 27 | V17: 20343 | W17: =X17+Y17+Z17 -> 739 | X17: 135 | Y17: 0 | Z17: 604 | AA17: 0 | AB17: 0 | AC17: 0 | AD17: 0 | AE17: =AE16+AB17-AC17-AD17 -> 101
A18: 45915 | B18: 월 | C18: 12 | D18: 0 | E18: =C18+D18 -> 12 | F18: 5 | G18: 10 | H18: 0 | I18: =F18+G18+H18 -> 15 | J18: 0 | K18: 메가와리 출고 / 라벨 2 | L18: 11 | N18: 5 | P18: 90~210 | Q18: 메가와리 출고 | R18: =S18+X18 -> 14500 | S18: =T18+U18+V18 -> 12392 | T18: 0 | U18: 9 | V18: 12383 | W18: =X18+Y18+Z18 -> 2825 | X18: 2108 | Y18: 46 | Z18: 671 | AA18: 2 | AB18: 248 | AC18: 0 | AD18: 0 | AE18: =AE17+AB18-AC18-AD18 -> 349
A19: 45916 | B19: 화 | C19: 12 | D19: 0 | E19: =C19+D19 -> 12 | F19: 5 | G19: 10 | H19: 0 | I19: =F19+G19+H19 -> 15 | J19: 0 | K19: 출고 8 / 라벨 2 | L19: 2 | N19: 0 | O19: 0 | P19: 210 | Q19: 풀필먼트 잔업 | R19: =S19+X19 -> 11081 | S19: =T19+U19+V19 -> 10309 | T19: 0 | U19: 26 | V19: 10283 | W19: =X19+Y19+Z19 -> 3488 | X19: 772 | Y19: 25 | Z19: 2691 | AA19: 5 | AB19: 63 | AC19: 0 | AD19: 0 | AE19: =AE18+AB19-AC19-AD19 -> 412
A20: 45917 | B20: 수 | C20: 10 | D20: 0 | E20: =C20+D20 -> 10 | F20: 5 | G20: 12 | H20: 0 | I20: =F20+G20+H20 -> 17 | J20: 0 | K20: 출고10/라벨 2 | L20: 3 | N20: 0 | O20: 0 | P20: 360 | Q20: 풀필먼트 잔업 | R20: =S20+X20 -> 13476 | S20: =T20+U20+V20 -> 12342 | T20: 0 | U20: 69 | V20: 12273 | W20: =X20+Y20+Z20 -> 2190 | X20: 1134 | Y20: 101 | Z20: 955 | AA20: 5 | AB20: 76 | AC20: 270 | AD20: 0 | AE20: =AE19+AB20-AC20-AD20 -> 218
A21: 45918 | B21: 목 | C21: 11 | D21: 0 | E21: =C21+D21 -> 11 | F21: 5 | G21: =2+4+2 -> 8 | H21: 0 | I21: =F21+G21+H21 -> 13 | J21: 0 | K21: 출고8 | L21: 4 | N21: 0 | O21: 0 | P21: 360 | Q21: 레이아웃 변경 | R21: =S21+X21 -> 6771 | S21: =T21+U21+V21 -> 5669 | T21: 0 | U21: 37 | V21: 5632 | W21: =X21+Y21+Z21 -> 1973 | X21: 1102 | Y21: 15 | Z21: 856 | AA21: 6 | AB21: 0 | AC21: 0 | AD21: 0 | AE21: =AE20+AB21-AC21-AD21 -> 218
A22: 45919 | B22: 금 | C22: 11 | D22: 0 | E22: =C22+D22 -> 11 | F22: 5 | G22: 9 | H22: 0 | I22: =F22+G22+H22 -> 14 | J22: 0 | K22: 출고 7 / 라벨 2 | L22: 1 | N22: 0 | O22: 0 | P22: 420 | Q22: B2B | R22: =S22+X22 -> 6602 | S22: =T22+U22+V22 -> 5570 | T22: 0 | U22: 127 | V22: 5443 | W22: =X22+Y22+Z22 -> 1540 | X22: 1032 | Y22: 17 | Z22: 491 | AA22: 12 | AB22: 0 | AC22: 49 | AD22: 0 | AE22: =AE21+AB22-AC22-AD22 -> 169
A23: 45920 | B23: 토 | C23: 2 | D23: 0 | E23: =C23+D23 -> 2 | F23: 0 | G23: 0 | H23: 0 | I23: =F23+G23+H23 -> 0 | J23: 0 | R23: =S23+X23 -> 28 | S23: =T23+U23+V23 -> 28 | T23: 0 | U23: 0 | V23: 28 | W23: =X23+Y23+Z23 -> 159 | X23: 0 | Y23: 131 | Z23: 28 | AA23: 0 | AB23: 0 | AC23: 0 | AD23: 0 | AE23: =AE22+AB23-AC23-AD23 -> 169
A24: 45921 | B24: 일 | C24: 2 | D24: 0 | E24: =C24+D24 -> 2 | F24: 0 | G24: 0 | H24: 0 | I24: =F24+G24+H24 -> 0 | J24: 0 | R24: =S24+X24 -> 314 | S24: =T24+U24+V24 -> 314 | T24: 0 | U24: 0 | V24: 314 | W24: =X24+Y24+Z24 -> 322 | X24: 0 | Y24: 23 | Z24: 299 | AA24: 0 | AB24: 0 | AC24: 0 | AD24: 0 | AE24: =AE23+AB24-AC24-AD24 -> 169
A25: 45922 | B25: 월 | C25: 12 | D25: 0 | E25: =C25+D25 -> 12 | F25: 5 | G25: 8 | H25: 0 | I25: =F25+G25+H25 -> 13 | J25: 0 | K25: 출고 6 / 라벨 2 | L25: 3 | N25: 0 | O25: 0 | P25: 360 | Q25: 풀필먼트 잔업 | R25: =S25+X25 -> 5238 | S25: =T25+U25+V25 -> 3030 | T25: 0 | U25: 34 | V25: 2996 | W25: =X25+Y25+Z25 -> 2676 | X25: 2208 | Y25: 50 | Z25: 418 | AA25: 6 | AB25: 0 | AC25: 0 | AD25: 0 | AE25: =AE24+AB25-AC25-AD25 -> 169
A26: 45923 | B26: 화 | C26: 11 | D26: 0 | E26: =C26+D26 -> 11 | F26: 5 | G26: 9 | H26: 0 | I26: =F26+G26+H26 -> 14 | J26: 0 | K26: 출고7/ 라벨2 | L26: 2 | N26: 0 | O26: 0 | P26: 270 | Q26: 풀필먼트 잔업 | R26: =S26+X26 -> 5141 | S26: =T26+U26+V26 -> 4272 | T26: 0 | U26: 75 | V26: 4197 | W26: =X26+Y26+Z26 -> 2676 | X26: 869 | Y26: 26 | Z26: 1781 | AA26: 7 | AB26: 0 | AC26: 0 | AD26: 0 | AE26: =AE25+AB26-AC26-AD26 -> 169
A27: 45924 | B27: 수 | C27: 12 | D27: 0 | E27: =C27+D27 -> 12 | F27: 5 | G27: 7 | H27: 0 | I27: =F27+G27+H27 -> 12 | J27: 0 | K27: 출고6/ 라벨1 | L27: 3 | N27: 0 | O27: 0 | P27: 120~210 | Q27: 풀필먼트 잔업 | R27: =S27+X27 -> 5401 | S27: =T27+U27+V27 -> 4559 | T27: 0 | U27: 81 | V27: 4478 | W27: =X27+Y27+Z27 -> 1516 | X27: 842 | Y27: 72 | Z27: 602 | AA27: 10 | AB27: 499 | AC27: 0 | AD27: 0 | AE27: =AE26+AB27-AC27-AD27 -> 668
A28: 45925 | B28: 목 | C28: 12 | D28: 0 | E28: =C28+D28 -> 12 | F28: 5 | G28: 8 | H28: 0 | I28: =F28+G28+H28 -> 13 | J28: 0 | K28: 출고 6 / 라벨 2 | L28: 4 | N28: 0 | O28: 0 | P28: 120 | Q28: 풀필먼트 잔업 (쉽너지) | R28: =S28+X28 -> 3115 | S28: =T28+U28+V28 -> 2258 | T28: 0 | U28: 33 | V28: 2225 | W28: =X28+Y28+Z28 -> 1416 | X28: 857 | Y28: 25 | Z28: 534 | AA28: 9 | AB28: 28 | AC28: 0 | AD28: 114 | AE28: =AE27+AB28-AC28-AD28 -> 582
A29: 45926 | B29: 금 | C29: 10.5 | D29: 0 | E29: =C29+D29 -> 10.5 | F29: 5 | G29: 8 | H29: 0 | I29: =F29+G29+H29 -> 13 | J29: 0 | K29: 출고 6 / 라벨 2 | R29: =S29+X29 -> 3556 | S29: =T29+U29+V29 -> 2601 | T29: 0 | U29: 55 | V29: 2546 | W29: =X29+Y29+Z29 -> 1588 | X29: 955 | Y29: 130 | Z29: 503 | AA29: 2 | AC29: 511
A30: 45927 | B30: 토 | C30: 2 | D30: 0 | E30: =C30+D30 -> 2 | F30: 0 | G30: 0 | H30: 0 | I30: =F30+G30+H30 -> 0 | J30: 0 | R30: =S30+X30 -> 22 | S30: =T30+U30+V30 -> 22 | T30: 0 | U30: 0 | V30: 22 | W30: =X30+Y30+Z30 -> 22 | X30: 0 | Y30: 0 | Z30: 22 | AA30: 0
A31: 45928 | B31: 일 | C31: 2 | D31: 0 | E31: =C31+D31 -> 2 | F31: 0 | G31: 0 | H31: 0 | I31: =F31+G31+H31 -> 0 | J31: 0 | R31: =S31+X31 -> 23 | S31: =T31+U31+V31 -> 23 | T31: 0 | U31: 0 | V31: 23 | W31: =X31+Y31+Z31 -> 23 | X31: 0 | Y31: 0 | Z31: 23 | AA31: 0
A32: 45929 | B32: 월 | C32: 12 | D32: 0 | E32: =C32+D32 -> 12 | F32: 5 | G32: 6 | H32: 0 | I32: =F32+G32+H32 -> 11 | J32: 0 | K32: 출고 4 / 라벨2 | L32: 11 | N32: 0 | O32: 0 | P32: 90~300 | Q32: 풀필먼트 잔업 | R32: =S32+X32 -> 4663 | S32: =T32+U32+V32 -> 2586 | T32: 0 | U32: 62 | V32: 2524 | W32: =X32+Y32+Z32 -> 2656 | X32: 2077 | Y32: 82 | Z32: 497 | AA32: 2
A33: 45930 | B33: 화 | C33: 13 | D33: 0 | E33: =C33+D33 -> 13 | F33: 5 | G33: 7 | H33: 0 | I33: =F33+G33+H33 -> 12 | J33: 0 | K33: 출고 5 / 라벨2 | L33: 3 | N33: 0 | O33: 0 | P33: 360 | Q33: 풀필먼트 / 퇴점 작업 / 정산 | R33: =S33+X33 -> 4383 | S33: =T33+U33+V33 -> 3594 | T33: 0 | U33: 67 | V33: 3527 | W33: =X33+Y33+Z33 -> 2320 | X33: 789 | Y33: 78 | Z33: 1453 | AA33: 2
A34: 합계 | C34: =SUM(C4:C33) -> 285 | D34: =SUM(D4:D33) -> 99 | E34: =SUM(E4:E33) -> 384 | F34: =SUM(F4:F33) -> 128 | G34: =SUM(G4:G33) -> 463.5 | H34: =SUM(H4:H33) -> 26 | I34: =SUM(I4:I33) -> 617.5 | J34: =SUM(J4:J33) -> 38 | L34: =SUM(L4:L33) -> 136 | N34: =SUM(N4:N33) -> 54 | O34: =SUM(O4:O33) -> 93 | P34: =SUM(P4:P33) -> 2580 | R34: =SUM(R4:R33) -> 443153 | S34: =SUM(S4:S33) -> 415484 | T34: =SUM(T4:T33) -> 0 | U34: =SUM(U4:U33) -> 1191 | V34: =SUM(V4:V33) -> 414293 | W34: =SUM(W4:W33) -> 91925 | X34: =SUM(X4:X33) -> 27669 | Y34: =SUM(Y4:Y33) -> 1442 | ... AD34: =SUM(AD4:AD33) -> 114
A35: ▣ 참고사항 (단기 충원 사유)
A36: ① OPS 단기 1명 고정 투입 중(입고 홍순호과장 퇴사 후 OPS 김필재대리 입고파트로 전환 배치 후 정직원이 아닌 단기 인력 투입)
A37: ② 월, 화 VTPL 출고 화물 (15시 기준) 당일 출고 (1~2명)
A38: ③ VTPL 국내 행사 사전 공유 시 1~2명 투입
A39: ④ B2B 출고 요청 작업 발생 시
A40: ⑤ 정직원 휴가 시 등등

Sheet 10월
A1: 일자 | B1: 요일 | J1: 운영 근무자 잔업 | P1: 영종ALL | Q1: OPS 출하건수 | U1: WMS 작업건수 (Fulfillment) | Z1: B2B | AA1: WMG | AE1: 비고
C2: 정직원 | E2: 협력사원 | H2: 야간 | I2: 단기충원사유
C3: OPS, QFC | D3: 합계 | E3: 장기협력사원 | F3: 단기협력사원 | G3: 합계 | H3: 단기협력사원 | J3: OPS, QFC | K3: 에러,입고,픽업 | L3: 장기협력사원 | M3: 단기협력사원 | N3: 잔업시간(분) | O3: 잔업사유 | P3: ALL | Q3: KR-All | R3: KRKR | S3: KR-Oversea | T3: KRJP | U3: KR-All | V3: KRKR | W3: KR-Oversea | Y3: KRJP | Z3: 출고 건수 | AA3: 입고건수 | AB3: 출고건수 | AC3: 반송 | AD3: 미출고
W4: WMS | X4: 이벗매니저
A5: 45931 | B5: 수 | C5: 13 | D5: =C5 -> 13 | E5: 5 | F5: 7 | G5: =E5+F5 -> 12 | I5: 메가포, 출고 5 / 라벨 2 | J5: 3 | N5: 210~270 | O5: 풀필먼트 (입고 / 정산 / B2B) | P5: =Q5+V5+X5 -> 4892 | Q5: =R5+S5+T5 -> 3978 | R5: 0 | S5: 103 | T5: 3875 | U5: =V5+W5+Y5+X5 -> 1501 | V5: 900 | W5: 3 | X5: 14 | Y5: 584 | Z5: 7
A6: 45932 | B6: 목 | C6: 12 | D6: =C6 -> 12 | E6: 4 | F6: 7 | G6: =E6+F6 -> 11 | I6: 메가포, 출고 5 / 라벨 2 | J6: 11 | N6: 120 | O6: 풀필먼트 / ops 출고 | P6: =Q6+V6+X6 -> 6209 | Q6: =R6+S6+T6 -> 5559 | R6: 0 | S6: 87 | T6: 5472 | U6: =V6+W6+Y6+X6 -> 1865 | V6: 631 | W6: 1 | X6: 19 | Y6: 1214 | Z6: 1
A7: 45933 | B7: 금 | C7: 1 | D7: =C7 -> 1 | E7: 0 | F7: 0 | G7: =E7+F7 -> 0 | I7: 메가포 | P7: =Q7+V7+X7 -> 148 | Q7: =R7+S7+T7 -> 148 | R7: 0 | S7: 0 | T7: 148 | U7: =V7+W7+Y7+X7 -> 148 | V7: 0 | W7: 0 | X7: 0 | Y7: 148 | Z7: 0
A8: 45934 | B8: 토 | C8: 0 | D8: =C8 -> 0 | E8: 0 | F8: 0 | G8: =E8+F8 -> 0 | P8: =Q8+V8+X8 -> 0 | Q8: =R8+S8+T8 -> 0 | R8: 0 | S8: 0 | T8: 0 | U8: =V8+W8+Y8+X8 -> 0 | V8: 0 | W8: 0 | X8: 0 | Y8: 0 | Z8: 0
A9: 45935 | B9: 일 | C9: 0 | D9: =C9 -> 0 | E9: 0 | F9: 0 | G9: =E9+F9 -> 0 | P9: =Q9+V9+X9 -> 0 | Q9: =R9+S9+T9 -> 0 | R9: 0 | S9: 0 | T9: 0 | U9: =V9+W9+Y9+X9 -> 0 | V9: 0 | W9: 0 | X9: 0 | Y9: 0 | Z9: 0
A10: 45936 | B10: 월 | C10: 0 | D10: =C10 -> 0 | E10: 0 | F10: 0 | G10: =E10+F10 -> 0 | P10: =Q10+V10+X10 -> 0 | Q10: =R10+S10+T10 -> 0 | R10: 0 | S10: 0 | T10: 0 | U10: =V10+W10+Y10+X10 -> 0 | V10: 0 | W10: 0 | X10: 0 | Y10: 0 | Z10: 0
A11: 45937 | B11: 화 | C11: 0 | D11: =C11 -> 0 | E11: 0 | F11: 0 | G11: =E11+F11 -> 0 | P11: =Q11+V11+X11 -> 0 | Q11: =R11+S11+T11 -> 0 | R11: 0 | S11: 0 | T11: 0 | U11: =V11+W11+Y11+X11 -> 0 | V11: 0 | W11: 0 | X11: 0 | Y11: 0 | Z11: 0
A12: 45938 | B12: 수 | C12: 0 | D12: =C12 -> 0 | E12: 0 | F12: 0 | G12: =E12+F12 -> 0 | P12: =Q12+V12+X12 -> 0 | Q12: =R12+S12+T12 -> 0 | R12: 0 | S12: 0 | T12: 0 | U12: =V12+W12+Y12+X12 -> 0 | V12: 0 | W12: 0 | X12: 0 | Y12: 0 | Z12: 0
A13: 45939 | B13: 목 | C13: 3 | D13: =C13 -> 3 | E13: 0 | F13: 0 | G13: =E13+F13 -> 0 | P13: =Q13+V13+X13 -> 133 | Q13: =R13+S13+T13 -> 133 | R13: 0 | S13: 0 | T13: 133 | U13: =V13+W13+Y13+X13 -> 132 | V13: 0 | W13: 0 | X13: 0 | Y13: 132 | Z13: 0
A14: 45940 | B14: 금 | C14: 14 | D14: =C14 -> 14 | E14: 5 | F14: 28 | G14: =E14+F14 -> 33 | I14: 출고 28 / (연휴 물량 처리) | J14: 12 | L14: 5 | M14: =8+5+6 -> 19 | N14: 90~120 | O14: 풀필먼트 / ops 출고 | P14: =Q14+V14+X14 -> 14412 | Q14: =R14+S14+T14 -> 8652 | R14: 0 | S14: 28 | T14: 8624 | U14: =V14+W14+Y14+X14 -> 7202 | V14: 5633 | W14: 0 | X14: 127 | Y14: 1442 | Z14: 3
A15: 45941 | B15: 토 | C15: =14-3 -> 11 | D15: =C15 -> 11 | E15: 4 | F15: 3 | G15: =E15+F15 -> 7 | P15: =Q15+V15+X15 -> 5904 | Q15: =R15+S15+T15 -> 5799 | R15: 0 | S15: 8 | T15: 5791 | U15: =V15+W15+Y15+X15 -> 3459 | V15: 105 | W15: 4 | X15: 0 | Y15: 3350 | Z15: 0
A16: 45942 | B16: 일 | C16: 1 | D16: =C16 -> 1 | E16: 0 | F16: 0 | G16: =E16+F16 -> 0 | P16: =Q16+V16+X16 -> 31 | Q16: =R16+S16+T16 -> 31 | R16: 0 | S16: 0 | T16: 31 | U16: =V16+W16+Y16+X16 -> 31 | V16: 0 | W16: 0 | X16: 0 | Y16: 31 | Z16: 0
A17: 45943 | B17: 월 | C17: 14 | D17: =C17 -> 14 | E17: 4 | F17: 28 | G17: =E17+F17 -> 32 | I17: 출고 28 | J17: 2 | N17: 210 | O17: 풀필먼트 | P17: =Q17+V17+X17 -> 16694 | Q17: =R17+S17+T17 -> 13855 | R17: 0 | S17: 87 | T17: 13768 | U17: =V17+W17+Y17+X17 -> 4935 | V17: 2760 | W17: 4 | X17: 79 | Y17: 2092 | Z17: 2
A18: 45944 | B18: 화 | C18: 14 | D18: =C18 -> 14 | E18: 4 | F18: =3+3+4 -> 10 | G18: =E18+F18 -> 14 | I18: 출고 8 / 라벨 2 | J18: 1 | N18: 90 | O18: 풀필먼트 | P18: =Q18+V18+X18 -> 7762 | Q18: =R18+S18+T18 -> 6584 | R18: 0 | S18: 124 | T18: 6460 | U18: =V18+W18+Y18+X18 -> 2206 | V18: 1000 | W18: 9 | X18: 178 | Y18: 1019 | Z18: 2
A19: 45945 | B19: 수 | C19: 13 | D19: =C19 -> 13 | E19: 8 | F19: 6 | G19: =E19+F19 -> 14 | I19: 출고 4 / 라벨 2 | P19: =Q19+V19+X19 -> 7261 | Q19: =R19+S19+T19 -> 6347 | R19: 0 | S19: 145 | T19: 6202 | U19: =V19+W19+Y19+X19 -> 2118 | V19: 894 | W19: 2 | X19: 20 | Y19: 1202 | Z19: 4
A20: 45946 | B20: 목 | C20: 13.5 | D20: =C20 -> 13.5 | E20: 8 | F20: 4 | G20: =E20+F20 -> 12 | I20: 출고 2 / 라벨 2 | J20: 13 | O20: 디엑스엔브이엑스, 시온코스메틱 퇴점 작업 상상인터내셔날 행사로 물량 증가 (776건) | P20: =Q20+V20+X20 -> 5440 | Q20: =R20+S20+T20 -> 4254 | R20: 0 | S20: 123 | T20: 4131 | U20: =V20+W20+Y20+X20 -> 2253 | V20: 986 | W20: 6 | X20: 200 | Y20: 1061 | Z20: 2
A21: 45947 | B21: 금 | C21: 15 | D21: =C21 -> 15 | E21: 6 | F21: 11 | G21: =E21+F21 -> 17 | I21: 출고 11 | J21: 3 | N21: 120~150 | O21: B2B | P21: =Q21+V21+X21 -> 5264 | Q21: =R21+S21+T21 -> 4129 | R21: 0 | S21: 84 | T21: 4045 | U21: =V21+W21+Y21+X21 -> 2549 | V21: 931 | W21: 11 | X21: 204 | Y21: 1403 | Z21: 5
A22: 45948 | B22: 토 | C22: 2 | D22: =C22 -> 2 | E22: 0 | F22: 0 | G22: =E22+F22 -> 0 | P22: =Q22+V22+X22 -> 199 | Q22: =R22+S22+T22 -> 199 | R22: 0 | S22: 0 | T22: 199 | U22: =V22+W22+Y22+X22 -> 199 | V22: 0 | W22: 0 | X22: 0 | Y22: 199 | Z22: 0
A23: 45949 | B23: 일 | C23: 1 | D23: =C23 -> 1 | E23: 0 | F23: 0 | G23: =E23+F23 -> 0 | P23: =Q23+V23+X23 -> 29 | Q23: =R23+S23+T23 -> 29 | R23: 0 | S23: 0 | T23: 29 | U23: =V23+W23+Y23+X23 -> 29 | V23: 0 | W23: 0 | X23: 0 | Y23: 29 | Z23: 0
A24: 45950 | B24: 월 | C24: 14.5 | D24: =C24 -> 14.5 | E24: 8 | F24: 9 | G24: =E24+F24 -> 17 | I24: 출고 9 | J24: 14 | N24: 90~ | O24: 풀필먼트 / ops 출고 | P24: =Q24+V24+X24 -> 6846 | Q24: =R24+S24+T24 -> 4267 | R24: 0 | S24: 72 | T24: 4195 | U24: =V24+W24+Y24+X24 -> 3956 | V24: 2525 | W24: 2 | X24: 54 | Y24: 1375 | Z24: 2
A25: 45951 | B25: 화 | C25: 13 | D25: =C25 -> 13 | E25: 8 | F25: 8 | G25: =E25+F25 -> 16 | I25: 출고 8 | J25: 2 | N25: 120~ | O25: B2B / 입고 | P25: =Q25+V25+X25 -> 5370 | Q25: =R25+S25+T25 -> 4057 | R25: 0 | S25: 77 | T25: 3980 | U25: =V25+W25+Y25+X25 -> 2920 | V25: 995 | W25: 8 | X25: 318 | Y25: 1599 | Z25: 4
A26: 45952 | B26: 수 | C26: 12 | D26: =C26 -> 12 | E26: 8 | F26: 4 | G26: =E26+F26 -> 12 | I26: 출고 4 | J26: 3 | N26: 120~150 | O26: 재고조사 | P26: =Q26+V26+X26 -> 4621 | Q26: =R26+S26+T26 -> 3456 | R26: 0 | S26: 116 | T26: 3340 | U26: =V26+W26+Y26+X26 -> 2273 | V26: 944 | W26: 5 | X26: 221 | Y26: 1103 | Z26: 4
A27: 45953 | B27: 목 | C27: 13 | D27: =C27 -> 13 | E27: 8 | F27: 5 | G27: =E27+F27 -> 13 | I27: 출고 5 | J27: 2 | N27: 90~180 | O27: B2B | P27: =Q27+V27+X27 -> 3408 | Q27: =R27+S27+T27 -> 2272 | R27: 0 | S27: 55 | T27: 2217 | U27: =V27+W27+Y27+X27 -> 1680 | V27: 923 | W27: 3 | X27: 213 | Y27: 541 | Z27: 10
A28: 45954 | B28: 금 | C28: 13 | D28: =C28 -> 13 | E28: 8 | F28: 3 | G28: =E28+F28 -> 11 | I28: 출고 3 | P28: =Q28+V28+X28 -> 3508 | Q28: =R28+S28+T28 -> 2543 | R28: 0 | S28: 73 | T28: 2470 | U28: =V28+W28+Y28+X28 -> 1417 | V28: 946 | W28: 10 | X28: 19 | Y28: 442 | Z28: 3
A29: 45955 | B29: 토 | C29: 1 | D29: =C29 -> 1 | E29: 0 | F29: 0 | G29: =E29+F29 -> 0 | P29: =Q29+V29+X29 -> 25 | Q29: =R29+S29+T29 -> 25 | R29: 0 | S29: 0 | T29: 25 | U29: =V29+W29+Y29+X29 -> 25 | V29: 0 | W29: 0 | X29: 0 | Y29: 25 | Z29: 0
A30: 45956 | B30: 일 | C30: 1 | D30: =C30 -> 1 | E30: 0 | F30: 0 | G30: =E30+F30 -> 0 | P30: =Q30+V30+X30 -> 132 | Q30: =R30+S30+T30 -> 132 | R30: 0 | S30: 0 | T30: 132 | U30: =V30+W30+Y30+X30 -> 132 | V30: 0 | W30: 0 | X30: 0 | Y30: 132 | Z30: 0
A31: 45957 | B31: 월 | C31: 14 | D31: =C31 -> 14 | E31: 8 | F31: 10 | G31: =E31+F31 -> 18 | I31: 출고 10 | J31: 12 | N31: 90~ | O31: 풀필먼트 / ops 출고 | P31: =Q31+V31+X31 -> 6176 | Q31: =R31+S31+T31 -> 3876 | R31: 0 | S31: 127 | T31: 3749 | U31: =V31+W31+Y31+X31 -> 3083 | V31: 2243 | W31: 48 | X31: =9+48 -> 57 | Y31: 735 | Z31: 0
A32: 45958 | B32: 화 | C32: 14 | D32: =C32 -> 14 | E32: 8 | F32: 7 | G32: =E32+F32 -> 15 | I32: 출고 7 | P32: =Q32+V32+X32 -> 5832 | Q32: =R32+S32+T32 -> 4957 | R32: 0 | S32: 37 | T32: 4920 | U32: =V32+W32+Y32+X32 -> 2508 | V32: 866 | W32: 11 | X32: 9 | Y32: 1622 | Z32: 3
A33: 45959 | B33: 수 | C33: 13.5 | D33: =C33 -> 13.5 | E33: 8 | F33: 4 | G33: =E33+F33 -> 12 | I33: 출고 4 | P33: =Q33+V33+X33 -> 5622 | Q33: =R33+S33+T33 -> 4817 | R33: 0 | S33: 175 | T33: 4642 | U33: =V33+W33+Y33+X33 -> 1414 | V33: 797 | W33: 72 | X33: 8 | Y33: 537 | Z33: 4
A34: 45960 | B34: 목 | C34: 14 | D34: =C34 -> 14 | E34: 7 | F34: 4 | G34: =E34+F34 -> 11 | I34: 출고 4 | P34: =Q34+V34+X34 -> 3568 | Q34: =R34+S34+T34 -> 2769 | R34: 0 | S34: 64 | T34: 2705 | U34: =V34+W34+Y34+X34 -> 1551 | V34: 787 | W34: 29 | X34: 12 | Y34: 723 | Z34: 6
